Workbook

Sheet Printable
E15: Thirty Five Waterfront
E16: PAYMENT PLAN
D21: UNIT NUMBER | G21: 405
D22: SIZE SQM | G22: 120
D23: PRICE | G23: ='Payment Plan Simulator'!M5 -> 1900000
D24: VIEW | G24: Side Sea View
D25: MANAGEMENT FEES | G25: =+G23*0.02 -> 38000
D29: ='Payment Plan Simulator'!E5 -> Date | E29: ='Payment Plan Simulator'!F5 -> % | F29: ='Payment Plan Simulator'!G5 -> Amount | H29: Date | I29: % | J29: Amount
B30: =IF(E30=#REF!,$K$30,IF(E30=#REF!,$K$31,"instalment")) -> #REF! | D30: ='Payment Plan Simulator'!E6 -> 46327 | E30: ='Payment Plan Simulator'!F6 -> 0.05 | F30: ='Payment Plan Simulator'!G6 -> 95008 | H30: ='Payment Plan Simulator'!E41 -> 47392 | I30: ='Payment Plan Simulator'!F41 -> 0.013541667 | J30: ='Payment Plan Simulator'!G41 -> 25729
B31: =IF(E31=#REF!,$K$30,IF(E31=#REF!,$K$31,"instalment")) -> #REF! | D31: ='Payment Plan Simulator'!E7 -> 46357 | E31: ='Payment Plan Simulator'!F7 -> -2.3129646e-18 | F31: ='Payment Plan Simulator'!G7 -> 0 | H31: ='Payment Plan Simulator'!E42 -> 47423 | I31: ='Payment Plan Simulator'!F42 -> 0.013541667 | J31: ='Payment Plan Simulator'!G42 -> 25729
B32: =IF(E32=#REF!,$K$30,IF(E32=#REF!,$K$31,"instalment")) -> #REF! | D32: ='Payment Plan Simulator'!E8 -> 46388 | E32: ='Payment Plan Simulator'!F8 -> -2.3129646e-18 | F32: ='Payment Plan Simulator'!G8 -> 0 | H32: ='Payment Plan Simulator'!E43 -> 47453 | I32: ='Payment Plan Simulator'!F43 -> 0.013541667 | J32: ='Payment Plan Simulator'!G43 -> 25729
B33: =IF(E33=#REF!,$K$30,IF(E33=#REF!,$K$31,"instalment")) -> #REF! | D33: ='Payment Plan Simulator'!E9 -> 46419 | E33: ='Payment Plan Simulator'!F9 -> -2.3129646e-18 | F33: ='Payment Plan Simulator'!G9 -> 0 | H33: ='Payment Plan Simulator'!E44 -> 47484 | I33: ='Payment Plan Simulator'!F44 -> 0.013541667 | J33: ='Payment Plan Simulator'!G44 -> 25729
D34: ='Payment Plan Simulator'!E10 -> 46447 | E34: ='Payment Plan Simulator'!F10 -> -2.3129646e-18 | F34: ='Payment Plan Simulator'!G10 -> 0 | H34: ='Payment Plan Simulator'!E45 -> 47515 | I34: ='Payment Plan Simulator'!F45 -> 0.013541667 | J34: ='Payment Plan Simulator'!G45 -> 25729
D35: ='Payment Plan Simulator'!E11 -> 46478 | E35: ='Payment Plan Simulator'!F11 -> -2.3129646e-18 | F35: ='Payment Plan Simulator'!G11 -> 0 | H35: ='Payment Plan Simulator'!E46 -> 47543 | I35: ='Payment Plan Simulator'!F46 -> 0.013541667 | J35: ='Payment Plan Simulator'!G46 -> 25729
D36: ='Payment Plan Simulator'!E12 -> 46508 | E36: ='Payment Plan Simulator'!F12 -> -2.3129646e-18 | F36: ='Payment Plan Simulator'!G12 -> 0 | H36: ='Payment Plan Simulator'!E47 -> 47574 | I36: ='Payment Plan Simulator'!F47 -> 0.013541667 | J36: ='Payment Plan Simulator'!G47 -> 25729
D37: ='Payment Plan Simulator'!E13 -> 46539 | E37: ='Payment Plan Simulator'!F13 -> 0.3 | F37: ='Payment Plan Simulator'!G13 -> 570000 | H37: ='Payment Plan Simulator'!E48 -> 47604 | I37: ='Payment Plan Simulator'!F48 -> 0.013541667 | J37: ='Payment Plan Simulator'!G48 -> 25729
D38: ='Payment Plan Simulator'!E14 -> 46569 | E38: ='Payment Plan Simulator'!F14 -> 0.013541667 | F38: ='Payment Plan Simulator'!G14 -> 25729 | H38: ='Payment Plan Simulator'!E49 -> 47635 | I38: ='Payment Plan Simulator'!F49 -> 0.013541667 | J38: ='Payment Plan Simulator'!G49 -> 25729
D39: ='Payment Plan Simulator'!E15 -> 46600 | E39: ='Payment Plan Simulator'!F15 -> 0.013541667 | F39: ='Payment Plan Simulator'!G15 -> 25729 | H39: ='Payment Plan Simulator'!E50 -> 47665 | I39: ='Payment Plan Simulator'!F50 -> 0.013541667 | J39: ='Payment Plan Simulator'!G50 -> 25729
D40: ='Payment Plan Simulator'!E16 -> 46631 | E40: ='Payment Plan Simulator'!F16 -> 0.013541667 | F40: ='Payment Plan Simulator'!G16 -> 25729 | H40: ='Payment Plan Simulator'!E51 -> 47696 | I40: ='Payment Plan Simulator'!F51 -> 0.013541667 | J40: ='Payment Plan Simulator'!G51 -> 25729
D41: ='Payment Plan Simulator'!E17 -> 46661 | E41: ='Payment Plan Simulator'!F17 -> 0.013541667 | F41: ='Payment Plan Simulator'!G17 -> 25729 | H41: ='Payment Plan Simulator'!E52 -> 47727 | I41: ='Payment Plan Simulator'!F52 -> 0.013541667 | J41: ='Payment Plan Simulator'!G52 -> 25729
D42: ='Payment Plan Simulator'!E18 -> 46692 | E42: ='Payment Plan Simulator'!F18 -> 0.013541667 | F42: ='Payment Plan Simulator'!G18 -> 25729 | H42: ='Payment Plan Simulator'!E53 -> 47757 | I42: ='Payment Plan Simulator'!F53 -> 0.013541667 | J42: ='Payment Plan Simulator'!G53 -> 25729
D43: ='Payment Plan Simulator'!E19 -> 46722 | E43: ='Payment Plan Simulator'!F19 -> 0.013541667 | F43: ='Payment Plan Simulator'!G19 -> 25729 | H43: ='Payment Plan Simulator'!E54 -> 47788 | I43: ='Payment Plan Simulator'!F54 -> 0.013541667 | J43: ='Payment Plan Simulator'!G54 -> 25729
D44: ='Payment Plan Simulator'!E20 -> 46753 | E44: ='Payment Plan Simulator'!F20 -> 0.013541667 | F44: ='Payment Plan Simulator'!G20 -> 25729 | H44: ='Payment Plan Simulator'!E55 -> 47818 | I44: ='Payment Plan Simulator'!F55 -> 0.013541667 | J44: ='Payment Plan Simulator'!G55 -> 25729
D45: ='Payment Plan Simulator'!E21 -> 46784 | E45: ='Payment Plan Simulator'!F21 -> 0.013541667 | F45: ='Payment Plan Simulator'!G21 -> 25729 | H45: ='Payment Plan Simulator'!E56 -> 47849 | I45: ='Payment Plan Simulator'!F56 -> 0.013541667 | J45: ='Payment Plan Simulator'!G56 -> 25729 | K45: Frequency
D46: ='Payment Plan Simulator'!E22 -> 46813 | E46: ='Payment Plan Simulator'!F22 -> 0.013541667 | F46: ='Payment Plan Simulator'!G22 -> 25729 | H46: ='Payment Plan Simulator'!E57 -> 47880 | I46: ='Payment Plan Simulator'!F57 -> 0.013541667 | J46: ='Payment Plan Simulator'!G57 -> 25729
D47: ='Payment Plan Simulator'!E23 -> 46844 | E47: ='Payment Plan Simulator'!F23 -> 0.013541667 | F47: ='Payment Plan Simulator'!G23 -> 25729 | H47: ='Payment Plan Simulator'!E58 -> 47908 | I47: ='Payment Plan Simulator'!F58 -> 0.013541667 | J47: ='Payment Plan Simulator'!G58 -> 25729
D48: ='Payment Plan Simulator'!E24 -> 46874 | E48: ='Payment Plan Simulator'!F24 -> 0.013541667 | F48: ='Payment Plan Simulator'!G24 -> 25729 | H48: ='Payment Plan Simulator'!E59 -> 47939 | I48: ='Payment Plan Simulator'!F59 -> 0.013541667 | J48: ='Payment Plan Simulator'!G59 -> 25729
D49: ='Payment Plan Simulator'!E25 -> 46905 | E49: ='Payment Plan Simulator'!F25 -> 0.013541667 | F49: ='Payment Plan Simulator'!G25 -> 25729 | H49: ='Payment Plan Simulator'!E60 -> 47969 | I49: ='Payment Plan Simulator'!F60 -> 0.013541667 | J49: ='Payment Plan Simulator'!G60 -> 25729
D50: ='Payment Plan Simulator'!E26 -> 46935 | E50: ='Payment Plan Simulator'!F26 -> 0.013541667 | F50: ='Payment Plan Simulator'!G26 -> 25729 | H50: ='Payment Plan Simulator'!E61 -> 48000 | I50: ='Payment Plan Simulator'!F61 -> 0.013541667 | J50: ='Payment Plan Simulator'!G61 -> 25729
D51: ='Payment Plan Simulator'!E27 -> 46966 | E51: ='Payment Plan Simulator'!F27 -> 0.013541667 | F51: ='Payment Plan Simulator'!G27 -> 25729
D52: ='Payment Plan Simulator'!E28 -> 46997 | E52: ='Payment Plan Simulator'!F28 -> 0.013541667 | F52: ='Payment Plan Simulator'!G28 -> 25729
D53: ='Payment Plan Simulator'!E29 -> 47027 | E53: ='Payment Plan Simulator'!F29 -> 0.013541667 | F53: ='Payment Plan Simulator'!G29 -> 25729
D54: ='Payment Plan Simulator'!E30 -> 47058 | E54: ='Payment Plan Simulator'!F30 -> 0.013541667 | F54: ='Payment Plan Simulator'!G30 -> 25729
D55: ='Payment Plan Simulator'!E31 -> 47088 | E55: ='Payment Plan Simulator'!F31 -> 0.013541667 | F55: ='Payment Plan Simulator'!G31 -> 25729
D56: ='Payment Plan Simulator'!E32 -> 47119 | E56: ='Payment Plan Simulator'!F32 -> 0.013541667 | F56: ='Payment Plan Simulator'!G32 -> 25729
D57: ='Payment Plan Simulator'!E33 -> 47150 | E57: ='Payment Plan Simulator'!F33 -> 0.013541667 | F57: ='Payment Plan Simulator'!G33 -> 25729
D58: ='Payment Plan Simulator'!E34 -> 47178 | E58: ='Payment Plan Simulator'!F34 -> 0.013541667 | F58: ='Payment Plan Simulator'!G34 -> 25729 | H58: ='Payment Plan Simulator'!E69 | I58: ='Payment Plan Simulator'!F69 | J58: ='Payment Plan Simulator'!G69
D59: ='Payment Plan Simulator'!E35 -> 47209 | E59: ='Payment Plan Simulator'!F35 -> 0.013541667 | F59: ='Payment Plan Simulator'!G35 -> 25729 | H59: ='Payment Plan Simulator'!E70 | I59: ='Payment Plan Simulator'!F70 | J59: ='Payment Plan Simulator'!G70
D60: ='Payment Plan Simulator'!E36 -> 47239 | E60: ='Payment Plan Simulator'!F36 -> 0.013541667 | F60: ='Payment Plan Simulator'!G36 -> 25729 | H60: ='Payment Plan Simulator'!E71 | I60: ='Payment Plan Simulator'!F71 | J60: ='Payment Plan Simulator'!G71
D61: ='Payment Plan Simulator'!E37 -> 47270 | E61: ='Payment Plan Simulator'!F37 -> 0.013541667 | F61: ='Payment Plan Simulator'!G37 -> 25729 | H61: ='Payment Plan Simulator'!E72 | I61: ='Payment Plan Simulator'!F72 | J61: ='Payment Plan Simulator'!G72
...

Sheet Payment Plan Simulator
L3: INPUTS:
L4: Payment Basis | M4: Monthly
E5: Date | F5: % | G5: Amount | L5: Price: | M5: 1900000
D6: =IF(F6=$M$6,$L$6,IF(F6=$M$7,$L$7,"instalment")) -> Down Payment | E6: 46327 | F6: =M6 -> 0.05 | G6: =J8 -> 95008 | I6: Total % | J6: =+SUM(F6:F102) -> 1 | L6: Down Payment | M6: 0.05
D7: =IF(F7=$M$6,$L$6,IF(F7=$M$7,$L$7,"instalment")) -> instalment | E7: =IFERROR( IF( AND($M$9 >= E6, $M$9 <= EDATE(E6, $M$26), E6 <> $M$9), $M$9, IF( EDATE(E6, $M$26) <= EDATE($M$9, $M$13 * $M$26), EDATE(E6, $M$26), "" ) ), "") -> 46357 | F7: =IF(IFERROR(IF(INDEX($M$16:$M$23,MATCH(E7,$L$16:$L$23,0))=0,IF(E7<$M$9,$M$14,IF(E7=$M$9,$M$7,IF(E7="",0,$M$15))),INDEX($M$16:$M$23,MATCH(E7,$L$16:$L$23,0))),IF(E7<$M$9,$M$14,IF(E7=$M$9,$M$7,IF(E7="",0,$M$15))))=0,"",IFERROR(IF(INDEX($M$16:$M$23,MATCH(E7,$L$16:$L$23,0))=0,IF(E7<$M$9,$M$14,IF(E7=$M$9,$M$7,IF(E7="",0,$M$15))),INDEX($M$16:$M$23,MATCH(E7,$L$16:$L$23,0))),IF(E7<$M$9,$M$14,IF(E7=$M$9,$M$7,IF(E7="",0,$M$15))))) -> -2.3129646e-18 | G7: =IF(F7="","",IF(F7=0, 0, ROUNDDOWN(F7*$M$5,0.5))) -> 0 | I7: QAR | J7: =+SUM(G7:G102) -> 1804992 | L7: Handover | M7: 0.3
D8: =IF(F8=$M$6,$L$6,IF(F8=$M$7,$L$7,"instalment")) -> instalment | E8: =IFERROR(IF(AND($M$9 >= E7, $M$9 <= EDATE(E7, $M$26), E7 <> $M$9), $M$9, IF( EDATE(E7, $M$26) <= EDATE($M$9, $M$13 * $M$26), EDATE(E7, $M$26), "" ) ), "") -> 46388 | F8: =IF(IFERROR(IF(INDEX($M$16:$M$23,MATCH(E8,$L$16:$L$23,0))=0,IF(E8<$M$9,$M$14,IF(E8=$M$9,$M$7,IF(E8="",0,$M$15))),INDEX($M$16:$M$23,MATCH(E8,$L$16:$L$23,0))),IF(E8<$M$9,$M$14,IF(E8=$M$9,$M$7,IF(E8="",0,$M$15))))=0,"",IFERROR(IF(INDEX($M$16:$M$23,MATCH(E8,$L$16:$L$23,0))=0,IF(E8<$M$9,$M$14,IF(E8=$M$9,$M$7,IF(E8="",0,$M$15))),INDEX($M$16:$M$23,MATCH(E8,$L$16:$L$23,0))),IF(E8<$M$9,$M$14,IF(E8=$M$9,$M$7,IF(E8="",0,$M$15))))) -> -2.3129646e-18 | G8: =IF(F8="","",IF(F8=0, 0, ROUNDDOWN(F8*$M$5,0.5))) -> 0 | I8: Diff. | J8: =M5-J7 -> 95008 | L8: Handover requirement | M8: 0.35
D9: =IF(F9=$M$6,$L$6,IF(F9=$M$7,$L$7,"instalment")) -> instalment | E9: =IFERROR( IF( AND($M$9 >= E8, $M$9 <= EDATE(E8, $M$26), E8 <> $M$9), $M$9, IF( EDATE(E8, $M$26) <= EDATE($M$9, $M$13 * $M$26), EDATE(E8, $M$26), "" ) ), "") -> 46419 | F9: =IF(IFERROR(IF(INDEX($M$16:$M$23,MATCH(E9,$L$16:$L$23,0))=0,IF(E9<$M$9,$M$14,IF(E9=$M$9,$M$7,IF(E9="",0,$M$15))),INDEX($M$16:$M$23,MATCH(E9,$L$16:$L$23,0))),IF(E9<$M$9,$M$14,IF(E9=$M$9,$M$7,IF(E9="",0,$M$15))))=0,"",IFERROR(IF(INDEX($M$16:$M$23,MATCH(E9,$L$16:$L$23,0))=0,IF(E9<$M$9,$M$14,IF(E9=$M$9,$M$7,IF(E9="",0,$M$15))),INDEX($M$16:$M$23,MATCH(E9,$L$16:$L$23,0))),IF(E9<$M$9,$M$14,IF(E9=$M$9,$M$7,IF(E9="",0,$M$15))))) -> -2.3129646e-18 | G9: =IF(F9="","",IF(F9=0, 0, ROUNDDOWN(F9*$M$5,0.5))) -> 0 | I9: Gross | J9: =SUM(J7:J8) -> 1900000 | L9: Handover date | M9: 46539
D10: =IF(F10=$M$6,$L$6,IF(F10=$M$7,$L$7,"instalment")) -> instalment | E10: =IFERROR( IF( AND($M$9 >= E9, $M$9 <= EDATE(E9, $M$26), E9 <> $M$9), $M$9, IF( EDATE(E9, $M$26) <= EDATE($M$9, $M$13 * $M$26), EDATE(E9, $M$26), "" ) ), "") -> 46447 | F10: =IF(IFERROR(IF(INDEX($M$16:$M$23,MATCH(E10,$L$16:$L$23,0))=0,IF(E10<$M$9,$M$14,IF(E10=$M$9,$M$7,IF(E10="",0,$M$15))),INDEX($M$16:$M$23,MATCH(E10,$L$16:$L$23,0))),IF(E10<$M$9,$M$14,IF(E10=$M$9,$M$7,IF(E10="",0,$M$15))))=0,"",IFERROR(IF(INDEX($M$16:$M$23,MATCH(E10,$L$16:$L$23,0))=0,IF(E10<$M$9,$M$14,IF(E10=$M$9,$M$7,IF(E10="",0,$M$15))),INDEX($M$16:$M$23,MATCH(E10,$L$16:$L$23,0))),IF(E10<$M$9,$M$14,IF(E10=$M$9,$M$7,IF(E10="",0,$M$15))))) -> -2.3129646e-18 | G10: =IF(F10="","",IF(F10=0, 0, ROUNDDOWN(F10*$M$5,0.5))) -> 0 | J10: =J8=G6 -> TRUE | L10: Days to handover | M10: =M9-E6 -> 212
D11: =IF(F11=$M$6,$L$6,IF(F11=$M$7,$L$7,"instalment")) -> instalment | E11: =IFERROR( IF( AND($M$9 >= E10, $M$9 <= EDATE(E10, $M$26), E10 <> $M$9), $M$9, IF( EDATE(E10, $M$26) <= EDATE($M$9, $M$13 * $M$26), EDATE(E10, $M$26), "" ) ), "") -> 46478 | F11: =IF(IFERROR(IF(INDEX($M$16:$M$23,MATCH(E11,$L$16:$L$23,0))=0,IF(E11<$M$9,$M$14,IF(E11=$M$9,$M$7,IF(E11="",0,$M$15))),INDEX($M$16:$M$23,MATCH(E11,$L$16:$L$23,0))),IF(E11<$M$9,$M$14,IF(E11=$M$9,$M$7,IF(E11="",0,$M$15))))=0,"",IFERROR(IF(INDEX($M$16:$M$23,MATCH(E11,$L$16:$L$23,0))=0,IF(E11<$M$9,$M$14,IF(E11=$M$9,$M$7,IF(E11="",0,$M$15))),INDEX($M$16:$M$23,MATCH(E11,$L$16:$L$23,0))),IF(E11<$M$9,$M$14,IF(E11=$M$9,$M$7,IF(E11="",0,$M$15))))) -> -2.3129646e-18 | G11: =IF(F11="","",IF(F11=0, 0, ROUNDDOWN(F11*$M$5,0.5))) -> 0 | L11: Pre-handover Periodicity | M11: =IF(M25="Monthly", ROUNDDOWN(M10/(30 * $M$26), 0)-1, ROUNDDOWN(M10/(30 * $M$26), 0)) -> 6
D12: =IF(F12=$M$6,$L$6,IF(F12=$M$7,$L$7,"instalment")) -> instalment | E12: =IFERROR( IF( AND($M$9 >= E11, $M$9 <= EDATE(E11, $M$26), E11 <> $M$9), $M$9, IF( EDATE(E11, $M$26) <= EDATE($M$9, $M$13 * $M$26), EDATE(E11, $M$26), "" ) ), "") -> 46508 | F12: =IF(IFERROR(IF(INDEX($M$16:$M$23,MATCH(E12,$L$16:$L$23,0))=0,IF(E12<$M$9,$M$14,IF(E12=$M$9,$M$7,IF(E12="",0,$M$15))),INDEX($M$16:$M$23,MATCH(E12,$L$16:$L$23,0))),IF(E12<$M$9,$M$14,IF(E12=$M$9,$M$7,IF(E12="",0,$M$15))))=0,"",IFERROR(IF(INDEX($M$16:$M$23,MATCH(E12,$L$16:$L$23,0))=0,IF(E12<$M$9,$M$14,IF(E12=$M$9,$M$7,IF(E12="",0,$M$15))),INDEX($M$16:$M$23,MATCH(E12,$L$16:$L$23,0))),IF(E12<$M$9,$M$14,IF(E12=$M$9,$M$7,IF(E12="",0,$M$15))))) -> -2.3129646e-18 | G12: =IF(F12="","",IF(F12=0, 0, ROUNDDOWN(F12*$M$5,0.5))) -> 0 | L12: Post Handover Years | M12: 4
D13: =IF(F13=$M$6,$L$6,IF(F13=$M$7,$L$7,"instalment")) -> Handover | E13: =IFERROR( IF( AND($M$9 >= E12, $M$9 <= EDATE(E12, $M$26), E12 <> $M$9), $M$9, IF( EDATE(E12, $M$26) <= EDATE($M$9, $M$13 * $M$26), EDATE(E12, $M$26), "" ) ), "") -> 46539 | F13: =IF(IFERROR(IF(INDEX($M$16:$M$23,MATCH(E13,$L$16:$L$23,0))=0,IF(E13<$M$9,$M$14,IF(E13=$M$9,$M$7,IF(E13="",0,$M$15))),INDEX($M$16:$M$23,MATCH(E13,$L$16:$L$23,0))),IF(E13<$M$9,$M$14,IF(E13=$M$9,$M$7,IF(E13="",0,$M$15))))=0,"",IFERROR(IF(INDEX($M$16:$M$23,MATCH(E13,$L$16:$L$23,0))=0,IF(E13<$M$9,$M$14,IF(E13=$M$9,$M$7,IF(E13="",0,$M$15))),INDEX($M$16:$M$23,MATCH(E13,$L$16:$L$23,0))),IF(E13<$M$9,$M$14,IF(E13=$M$9,$M$7,IF(E13="",0,$M$15))))) -> 0.3 | G13: =IF(F13="","",IF(F13=0, 0, ROUNDDOWN(F13*$M$5,0.5))) -> 570000 | L13: Post-Handover Periodicity | M13: =M12 * (12 / $M$26) -> 48
D14: =IF(F14=$M$6,$L$6,IF(F14=$M$7,$L$7,"instalment")) -> instalment | E14: =IFERROR( IF( AND($M$9 >= E13, $M$9 <= EDATE(E13, $M$26), E13 <> $M$9), $M$9, IF( EDATE(E13, $M$26) <= EDATE($M$9, $M$13 * $M$26), EDATE(E13, $M$26), "" ) ), "") -> 46569 | F14: =IF(IFERROR(IF(INDEX($M$16:$M$23,MATCH(E14,$L$16:$L$23,0))=0,IF(E14<$M$9,$M$14,IF(E14=$M$9,$M$7,IF(E14="",0,$M$15))),INDEX($M$16:$M$23,MATCH(E14,$L$16:$L$23,0))),IF(E14<$M$9,$M$14,IF(E14=$M$9,$M$7,IF(E14="",0,$M$15))))=0,"",IFERROR(IF(INDEX($M$16:$M$23,MATCH(E14,$L$16:$L$23,0))=0,IF(E14<$M$9,$M$14,IF(E14=$M$9,$M$7,IF(E14="",0,$M$15))),INDEX($M$16:$M$23,MATCH(E14,$L$16:$L$23,0))),IF(E14<$M$9,$M$14,IF(E14=$M$9,$M$7,IF(E14="",0,$M$15))))) -> 0.013541667 | G14: =IF(F14="","",IF(F14=0, 0, ROUNDDOWN(F14*$M$5,0.5))) -> 25729 | L14: Pre-Handover pmt | M14: =(M8 - M7 - M6 - M21 - M22-M23) / (M11 - COUNTIF(M21:M23, ">0")) -> -2.3129646e-18
D15: =IF(F15=$M$6,$L$6,IF(F15=$M$7,$L$7,"instalment")) -> instalment | E15: =IFERROR( IF( AND($M$9 >= E14, $M$9 <= EDATE(E14, $M$26), E14 <> $M$9), $M$9, IF( EDATE(E14, $M$26) <= EDATE($M$9, $M$13 * $M$26), EDATE(E14, $M$26), "" ) ), "") -> 46600 | F15: =IF(IFERROR(IF(INDEX($M$16:$M$23,MATCH(E15,$L$16:$L$23,0))=0,IF(E15<$M$9,$M$14,IF(E15=$M$9,$M$7,IF(E15="",0,$M$15))),INDEX($M$16:$M$23,MATCH(E15,$L$16:$L$23,0))),IF(E15<$M$9,$M$14,IF(E15=$M$9,$M$7,IF(E15="",0,$M$15))))=0,"",IFERROR(IF(INDEX($M$16:$M$23,MATCH(E15,$L$16:$L$23,0))=0,IF(E15<$M$9,$M$14,IF(E15=$M$9,$M$7,IF(E15="",0,$M$15))),INDEX($M$16:$M$23,MATCH(E15,$L$16:$L$23,0))),IF(E15<$M$9,$M$14,IF(E15=$M$9,$M$7,IF(E15="",0,$M$15))))) -> 0.013541667 | G15: =IF(F15="","",IF(F15=0, 0, ROUNDDOWN(F15*$M$5,0.5))) -> 25729 | L15: Post-Handover pmt | M15: =(1 - M8 - SUM(M16:M20)) / (M13 - COUNTIF(M16:M20, ">0")) -> 0.013541667
D16: =IF(F16=$M$6,$L$6,IF(F16=$M$7,$L$7,"instalment")) -> instalment | E16: =IFERROR( IF( AND($M$9 >= E15, $M$9 <= EDATE(E15, $M$26), E15 <> $M$9), $M$9, IF( EDATE(E15, $M$26) <= EDATE($M$9, $M$13 * $M$26), EDATE(E15, $M$26), "" ) ), "") -> 46631 | F16: =IF(IFERROR(IF(INDEX($M$16:$M$23,MATCH(E16,$L$16:$L$23,0))=0,IF(E16<$M$9,$M$14,IF(E16=$M$9,$M$7,IF(E16="",0,$M$15))),INDEX($M$16:$M$23,MATCH(E16,$L$16:$L$23,0))),IF(E16<$M$9,$M$14,IF(E16=$M$9,$M$7,IF(E16="",0,$M$15))))=0,"",IFERROR(IF(INDEX($M$16:$M$23,MATCH(E16,$L$16:$L$23,0))=0,IF(E16<$M$9,$M$14,IF(E16=$M$9,$M$7,IF(E16="",0,$M$15))),INDEX($M$16:$M$23,MATCH(E16,$L$16:$L$23,0))),IF(E16<$M$9,$M$14,IF(E16=$M$9,$M$7,IF(E16="",0,$M$15))))) -> 0.013541667 | G16: =IF(F16="","",IF(F16=0, 0, ROUNDDOWN(F16*$M$5,0.5))) -> 25729 | L16: 46508 | M16: 0
D17: =IF(F17=$M$6,$L$6,IF(F17=$M$7,$L$7,"instalment")) -> instalment | E17: =IFERROR( IF( AND($M$9 >= E16, $M$9 <= EDATE(E16, $M$26), E16 <> $M$9), $M$9, IF( EDATE(E16, $M$26) <= EDATE($M$9, $M$13 * $M$26), EDATE(E16, $M$26), "" ) ), "") -> 46661 | F17: =IF(IFERROR(IF(INDEX($M$16:$M$23,MATCH(E17,$L$16:$L$23,0))=0,IF(E17<$M$9,$M$14,IF(E17=$M$9,$M$7,IF(E17="",0,$M$15))),INDEX($M$16:$M$23,MATCH(E17,$L$16:$L$23,0))),IF(E17<$M$9,$M$14,IF(E17=$M$9,$M$7,IF(E17="",0,$M$15))))=0,"",IFERROR(IF(INDEX($M$16:$M$23,MATCH(E17,$L$16:$L$23,0))=0,IF(E17<$M$9,$M$14,IF(E17=$M$9,$M$7,IF(E17="",0,$M$15))),INDEX($M$16:$M$23,MATCH(E17,$L$16:$L$23,0))),IF(E17<$M$9,$M$14,IF(E17=$M$9,$M$7,IF(E17="",0,$M$15))))) -> 0.013541667 | G17: =IF(F17="","",IF(F17=0, 0, ROUNDDOWN(F17*$M$5,0.5))) -> 25729 | K17: POST | L17: 46874 | M17: 0
D18: =IF(F18=$M$6,$L$6,IF(F18=$M$7,$L$7,"instalment")) -> instalment | E18: =IFERROR( IF( AND($M$9 >= E17, $M$9 <= EDATE(E17, $M$26), E17 <> $M$9), $M$9, IF( EDATE(E17, $M$26) <= EDATE($M$9, $M$13 * $M$26), EDATE(E17, $M$26), "" ) ), "") -> 46692 | F18: =IF(IFERROR(IF(INDEX($M$16:$M$23,MATCH(E18,$L$16:$L$23,0))=0,IF(E18<$M$9,$M$14,IF(E18=$M$9,$M$7,IF(E18="",0,$M$15))),INDEX($M$16:$M$23,MATCH(E18,$L$16:$L$23,0))),IF(E18<$M$9,$M$14,IF(E18=$M$9,$M$7,IF(E18="",0,$M$15))))=0,"",IFERROR(IF(INDEX($M$16:$M$23,MATCH(E18,$L$16:$L$23,0))=0,IF(E18<$M$9,$M$14,IF(E18=$M$9,$M$7,IF(E18="",0,$M$15))),INDEX($M$16:$M$23,MATCH(E18,$L$16:$L$23,0))),IF(E18<$M$9,$M$14,IF(E18=$M$9,$M$7,IF(E18="",0,$M$15))))) -> 0.013541667 | G18: =IF(F18="","",IF(F18=0, 0, ROUNDDOWN(F18*$M$5,0.5))) -> 25729 | K18: POST | L18: 47239 | M18: 0
D19: =IF(F19=$M$6,$L$6,IF(F19=$M$7,$L$7,"instalment")) -> instalment | E19: =IFERROR( IF( AND($M$9 >= E18, $M$9 <= EDATE(E18, $M$26), E18 <> $M$9), $M$9, IF( EDATE(E18, $M$26) <= EDATE($M$9, $M$13 * $M$26), EDATE(E18, $M$26), "" ) ), "") -> 46722 | F19: =IF(IFERROR(IF(INDEX($M$16:$M$23,MATCH(E19,$L$16:$L$23,0))=0,IF(E19<$M$9,$M$14,IF(E19=$M$9,$M$7,IF(E19="",0,$M$15))),INDEX($M$16:$M$23,MATCH(E19,$L$16:$L$23,0))),IF(E19<$M$9,$M$14,IF(E19=$M$9,$M$7,IF(E19="",0,$M$15))))=0,"",IFERROR(IF(INDEX($M$16:$M$23,MATCH(E19,$L$16:$L$23,0))=0,IF(E19<$M$9,$M$14,IF(E19=$M$9,$M$7,IF(E19="",0,$M$15))),INDEX($M$16:$M$23,MATCH(E19,$L$16:$L$23,0))),IF(E19<$M$9,$M$14,IF(E19=$M$9,$M$7,IF(E19="",0,$M$15))))) -> 0.013541667 | G19: =IF(F19="","",IF(F19=0, 0, ROUNDDOWN(F19*$M$5,0.5))) -> 25729 | K19: POST | L19: 47604 | M19: 0
D20: =IF(F20=$M$6,$L$6,IF(F20=$M$7,$L$7,"instalment")) -> instalment | E20: =IFERROR( IF( AND($M$9 >= E19, $M$9 <= EDATE(E19, $M$26), E19 <> $M$9), $M$9, IF( EDATE(E19, $M$26) <= EDATE($M$9, $M$13 * $M$26), EDATE(E19, $M$26), "" ) ), "") -> 46753 | F20: =IF(IFERROR(IF(INDEX($M$16:$M$23,MATCH(E20,$L$16:$L$23,0))=0,IF(E20<$M$9,$M$14,IF(E20=$M$9,$M$7,IF(E20="",0,$M$15))),INDEX($M$16:$M$23,MATCH(E20,$L$16:$L$23,0))),IF(E20<$M$9,$M$14,IF(E20=$M$9,$M$7,IF(E20="",0,$M$15))))=0,"",IFERROR(IF(INDEX($M$16:$M$23,MATCH(E20,$L$16:$L$23,0))=0,IF(E20<$M$9,$M$14,IF(E20=$M$9,$M$7,IF(E20="",0,$M$15))),INDEX($M$16:$M$23,MATCH(E20,$L$16:$L$23,0))),IF(E20<$M$9,$M$14,IF(E20=$M$9,$M$7,IF(E20="",0,$M$15))))) -> 0.013541667 | G20: =IF(F20="","",IF(F20=0, 0, ROUNDDOWN(F20*$M$5,0.5))) -> 25729 | K20: POST | L20: 47969 | M20: 0
D21: =IF(F21=$M$6,$L$6,IF(F21=$M$7,$L$7,"instalment")) -> instalment | E21: =IFERROR( IF( AND($M$9 >= E20, $M$9 <= EDATE(E20, $M$26), E20 <> $M$9), $M$9, IF( EDATE(E20, $M$26) <= EDATE($M$9, $M$13 * $M$26), EDATE(E20, $M$26), "" ) ), "") -> 46784 | F21: =IF(IFERROR(IF(INDEX($M$16:$M$23,MATCH(E21,$L$16:$L$23,0))=0,IF(E21<$M$9,$M$14,IF(E21=$M$9,$M$7,IF(E21="",0,$M$15))),INDEX($M$16:$M$23,MATCH(E21,$L$16:$L$23,0))),IF(E21<$M$9,$M$14,IF(E21=$M$9,$M$7,IF(E21="",0,$M$15))))=0,"",IFERROR(IF(INDEX($M$16:$M$23,MATCH(E21,$L$16:$L$23,0))=0,IF(E21<$M$9,$M$14,IF(E21=$M$9,$M$7,IF(E21="",0,$M$15))),INDEX($M$16:$M$23,MATCH(E21,$L$16:$L$23,0))),IF(E21<$M$9,$M$14,IF(E21=$M$9,$M$7,IF(E21="",0,$M$15))))) -> 0.013541667 | G21: =IF(F21="","",IF(F21=0, 0, ROUNDDOWN(F21*$M$5,0.5))) -> 25729 | K21: PRE | M21: 0
D22: =IF(F22=$M$6,$L$6,IF(F22=$M$7,$L$7,"instalment")) -> instalment | E22: =IFERROR( IF( AND($M$9 >= E21, $M$9 <= EDATE(E21, $M$26), E21 <> $M$9), $M$9, IF( EDATE(E21, $M$26) <= EDATE($M$9, $M$13 * $M$26), EDATE(E21, $M$26), "" ) ), "") -> 46813 | F22: =IF(IFERROR(IF(INDEX($M$16:$M$23,MATCH(E22,$L$16:$L$23,0))=0,IF(E22<$M$9,$M$14,IF(E22=$M$9,$M$7,IF(E22="",0,$M$15))),INDEX($M$16:$M$23,MATCH(E22,$L$16:$L$23,0))),IF(E22<$M$9,$M$14,IF(E22=$M$9,$M$7,IF(E22="",0,$M$15))))=0,"",IFERROR(IF(INDEX($M$16:$M$23,MATCH(E22,$L$16:$L$23,0))=0,IF(E22<$M$9,$M$14,IF(E22=$M$9,$M$7,IF(E22="",0,$M$15))),INDEX($M$16:$M$23,MATCH(E22,$L$16:$L$23,0))),IF(E22<$M$9,$M$14,IF(E22=$M$9,$M$7,IF(E22="",0,$M$15))))) -> 0.013541667 | G22: =IF(F22="","",IF(F22=0, 0, ROUNDDOWN(F22*$M$5,0.5))) -> 25729 | K22: PRE | M22: 0
D23: =IF(F23=$M$6,$L$6,IF(F23=$M$7,$L$7,"instalment")) -> instalment | E23: =IFERROR( IF( AND($M$9 >= E22, $M$9 <= EDATE(E22, $M$26), E22 <> $M$9), $M$9, IF( EDATE(E22, $M$26) <= EDATE($M$9, $M$13 * $M$26), EDATE(E22, $M$26), "" ) ), "") -> 46844 | F23: =IF(IFERROR(IF(INDEX($M$16:$M$23,MATCH(E23,$L$16:$L$23,0))=0,IF(E23<$M$9,$M$14,IF(E23=$M$9,$M$7,IF(E23="",0,$M$15))),INDEX($M$16:$M$23,MATCH(E23,$L$16:$L$23,0))),IF(E23<$M$9,$M$14,IF(E23=$M$9,$M$7,IF(E23="",0,$M$15))))=0,"",IFERROR(IF(INDEX($M$16:$M$23,MATCH(E23,$L$16:$L$23,0))=0,IF(E23<$M$9,$M$14,IF(E23=$M$9,$M$7,IF(E23="",0,$M$15))),INDEX($M$16:$M$23,MATCH(E23,$L$16:$L$23,0))),IF(E23<$M$9,$M$14,IF(E23=$M$9,$M$7,IF(E23="",0,$M$15))))) -> 0.013541667 | G23: =IF(F23="","",IF(F23=0, 0, ROUNDDOWN(F23*$M$5,0.5))) -> 25729 | K23: PRE | M23: 0
D24: =IF(F24=$M$6,$L$6,IF(F24=$M$7,$L$7,"instalment")) -> instalment | E24: =IFERROR( IF( AND($M$9 >= E23, $M$9 <= EDATE(E23, $M$26), E23 <> $M$9), $M$9, IF( EDATE(E23, $M$26) <= EDATE($M$9, $M$13 * $M$26), EDATE(E23, $M$26), "" ) ), "") -> 46874 | F24: =IF(IFERROR(IF(INDEX($M$16:$M$23,MATCH(E24,$L$16:$L$23,0))=0,IF(E24<$M$9,$M$14,IF(E24=$M$9,$M$7,IF(E24="",0,$M$15))),INDEX($M$16:$M$23,MATCH(E24,$L$16:$L$23,0))),IF(E24<$M$9,$M$14,IF(E24=$M$9,$M$7,IF(E24="",0,$M$15))))=0,"",IFERROR(IF(INDEX($M$16:$M$23,MATCH(E24,$L$16:$L$23,0))=0,IF(E24<$M$9,$M$14,IF(E24=$M$9,$M$7,IF(E24="",0,$M$15))),INDEX($M$16:$M$23,MATCH(E24,$L$16:$L$23,0))),IF(E24<$M$9,$M$14,IF(E24=$M$9,$M$7,IF(E24="",0,$M$15))))) -> 0.013541667 | G24: =IF(F24="","",IF(F24=0, 0, ROUNDDOWN(F24*$M$5,0.5))) -> 25729
D25: =IF(F25=$M$6,$L$6,IF(F25=$M$7,$L$7,"instalment")) -> instalment | E25: =IFERROR( IF( AND($M$9 >= E24, $M$9 <= EDATE(E24, $M$26), E24 <> $M$9), $M$9, IF( EDATE(E24, $M$26) <= EDATE($M$9, $M$13 * $M$26), EDATE(E24, $M$26), "" ) ), "") -> 46905 | F25: =IF(IFERROR(IF(INDEX($M$16:$M$23,MATCH(E25,$L$16:$L$23,0))=0,IF(E25<$M$9,$M$14,IF(E25=$M$9,$M$7,IF(E25="",0,$M$15))),INDEX($M$16:$M$23,MATCH(E25,$L$16:$L$23,0))),IF(E25<$M$9,$M$14,IF(E25=$M$9,$M$7,IF(E25="",0,$M$15))))=0,"",IFERROR(IF(INDEX($M$16:$M$23,MATCH(E25,$L$16:$L$23,0))=0,IF(E25<$M$9,$M$14,IF(E25=$M$9,$M$7,IF(E25="",0,$M$15))),INDEX($M$16:$M$23,MATCH(E25,$L$16:$L$23,0))),IF(E25<$M$9,$M$14,IF(E25=$M$9,$M$7,IF(E25="",0,$M$15))))) -> 0.013541667 | G25: =IF(F25="","",IF(F25=0, 0, ROUNDDOWN(F25*$M$5,0.5))) -> 25729 | L25: Frequency | M25: =M4 -> Monthly
D26: =IF(F26=$M$6,$L$6,IF(F26=$M$7,$L$7,"instalment")) -> instalment | E26: =IFERROR( IF( AND($M$9 >= E25, $M$9 <= EDATE(E25, $M$26), E25 <> $M$9), $M$9, IF( EDATE(E25, $M$26) <= EDATE($M$9, $M$13 * $M$26), EDATE(E25, $M$26), "" ) ), "") -> 46935 | F26: =IF(IFERROR(IF(INDEX($M$16:$M$23,MATCH(E26,$L$16:$L$23,0))=0,IF(E26<$M$9,$M$14,IF(E26=$M$9,$M$7,IF(E26="",0,$M$15))),INDEX($M$16:$M$23,MATCH(E26,$L$16:$L$23,0))),IF(E26<$M$9,$M$14,IF(E26=$M$9,$M$7,IF(E26="",0,$M$15))))=0,"",IFERROR(IF(INDEX($M$16:$M$23,MATCH(E26,$L$16:$L$23,0))=0,IF(E26<$M$9,$M$14,IF(E26=$M$9,$M$7,IF(E26="",0,$M$15))),INDEX($M$16:$M$23,MATCH(E26,$L$16:$L$23,0))),IF(E26<$M$9,$M$14,IF(E26=$M$9,$M$7,IF(E26="",0,$M$15))))) -> 0.013541667 | G26: =IF(F26="","",IF(F26=0, 0, ROUNDDOWN(F26*$M$5,0.5))) -> 25729 | M26: =CHOOSE(MATCH(M25, {"Annual","Semi Annual","Quarterly","Monthly"}, 0), 12, 6, 3, 1) -> 1
D27: =IF(F27=$M$6,$L$6,IF(F27=$M$7,$L$7,"instalment")) -> instalment | E27: =IFERROR( IF( AND($M$9 >= E26, $M$9 <= EDATE(E26, $M$26), E26 <> $M$9), $M$9, IF( EDATE(E26, $M$26) <= EDATE($M$9, $M$13 * $M$26), EDATE(E26, $M$26), "" ) ), "") -> 46966 | F27: =IF(IFERROR(IF(INDEX($M$16:$M$23,MATCH(E27,$L$16:$L$23,0))=0,IF(E27<$M$9,$M$14,IF(E27=$M$9,$M$7,IF(E27="",0,$M$15))),INDEX($M$16:$M$23,MATCH(E27,$L$16:$L$23,0))),IF(E27<$M$9,$M$14,IF(E27=$M$9,$M$7,IF(E27="",0,$M$15))))=0,"",IFERROR(IF(INDEX($M$16:$M$23,MATCH(E27,$L$16:$L$23,0))=0,IF(E27<$M$9,$M$14,IF(E27=$M$9,$M$7,IF(E27="",0,$M$15))),INDEX($M$16:$M$23,MATCH(E27,$L$16:$L$23,0))),IF(E27<$M$9,$M$14,IF(E27=$M$9,$M$7,IF(E27="",0,$M$15))))) -> 0.013541667 | G27: =IF(F27="","",IF(F27=0, 0, ROUNDDOWN(F27*$M$5,0.5))) -> 25729
D28: =IF(F28=$M$6,$L$6,IF(F28=$M$7,$L$7,"instalment")) -> instalment | E28: =IFERROR( IF( AND($M$9 >= E27, $M$9 <= EDATE(E27, $M$26), E27 <> $M$9), $M$9, IF( EDATE(E27, $M$26) <= EDATE($M$9, $M$13 * $M$26), EDATE(E27, $M$26), "" ) ), "") -> 46997 | F28: =IF(IFERROR(IF(INDEX($M$16:$M$23,MATCH(E28,$L$16:$L$23,0))=0,IF(E28<$M$9,$M$14,IF(E28=$M$9,$M$7,IF(E28="",0,$M$15))),INDEX($M$16:$M$23,MATCH(E28,$L$16:$L$23,0))),IF(E28<$M$9,$M$14,IF(E28=$M$9,$M$7,IF(E28="",0,$M$15))))=0,"",IFERROR(IF(INDEX($M$16:$M$23,MATCH(E28,$L$16:$L$23,0))=0,IF(E28<$M$9,$M$14,IF(E28=$M$9,$M$7,IF(E28="",0,$M$15))),INDEX($M$16:$M$23,MATCH(E28,$L$16:$L$23,0))),IF(E28<$M$9,$M$14,IF(E28=$M$9,$M$7,IF(E28="",0,$M$15))))) -> 0.013541667 | G28: =IF(F28="","",IF(F28=0, 0, ROUNDDOWN(F28*$M$5,0.5))) -> 25729
D29: =IF(F29=$M$6,$L$6,IF(F29=$M$7,$L$7,"instalment")) -> instalment | E29: =IFERROR( IF( AND($M$9 >= E28, $M$9 <= EDATE(E28, $M$26), E28 <> $M$9), $M$9, IF( EDATE(E28, $M$26) <= EDATE($M$9, $M$13 * $M$26), EDATE(E28, $M$26), "" ) ), "") -> 47027 | F29: =IF(IFERROR(IF(INDEX($M$16:$M$23,MATCH(E29,$L$16:$L$23,0))=0,IF(E29<$M$9,$M$14,IF(E29=$M$9,$M$7,IF(E29="",0,$M$15))),INDEX($M$16:$M$23,MATCH(E29,$L$16:$L$23,0))),IF(E29<$M$9,$M$14,IF(E29=$M$9,$M$7,IF(E29="",0,$M$15))))=0,"",IFERROR(IF(INDEX($M$16:$M$23,MATCH(E29,$L$16:$L$23,0))=0,IF(E29<$M$9,$M$14,IF(E29=$M$9,$M$7,IF(E29="",0,$M$15))),INDEX($M$16:$M$23,MATCH(E29,$L$16:$L$23,0))),IF(E29<$M$9,$M$14,IF(E29=$M$9,$M$7,IF(E29="",0,$M$15))))) -> 0.013541667 | G29: =IF(F29="","",IF(F29=0, 0, ROUNDDOWN(F29*$M$5,0.5))) -> 25729
D30: =IF(F30=$M$6,$L$6,IF(F30=$M$7,$L$7,"instalment")) -> instalment | E30: =IFERROR( IF( AND($M$9 >= E29, $M$9 <= EDATE(E29, $M$26), E29 <> $M$9), $M$9, IF( EDATE(E29, $M$26) <= EDATE($M$9, $M$13 * $M$26), EDATE(E29, $M$26), "" ) ), "") -> 47058 | F30: =IF(IFERROR(IF(INDEX($M$16:$M$23,MATCH(E30,$L$16:$L$23,0))=0,IF(E30<$M$9,$M$14,IF(E30=$M$9,$M$7,IF(E30="",0,$M$15))),INDEX($M$16:$M$23,MATCH(E30,$L$16:$L$23,0))),IF(E30<$M$9,$M$14,IF(E30=$M$9,$M$7,IF(E30="",0,$M$15))))=0,"",IFERROR(IF(INDEX($M$16:$M$23,MATCH(E30,$L$16:$L$23,0))=0,IF(E30<$M$9,$M$14,IF(E30=$M$9,$M$7,IF(E30="",0,$M$15))),INDEX($M$16:$M$23,MATCH(E30,$L$16:$L$23,0))),IF(E30<$M$9,$M$14,IF(E30=$M$9,$M$7,IF(E30="",0,$M$15))))) -> 0.013541667 | G30: =IF(F30="","",IF(F30=0, 0, ROUNDDOWN(F30*$M$5,0.5))) -> 25729
D31: =IF(F31=$M$6,$L$6,IF(F31=$M$7,$L$7,"instalment")) -> instalment | E31: =IFERROR( IF( AND($M$9 >= E30, $M$9 <= EDATE(E30, $M$26), E30 <> $M$9), $M$9, IF( EDATE(E30, $M$26) <= EDATE($M$9, $M$13 * $M$26), EDATE(E30, $M$26), "" ) ), "") -> 47088 | F31: =IF(IFERROR(IF(INDEX($M$16:$M$23,MATCH(E31,$L$16:$L$23,0))=0,IF(E31<$M$9,$M$14,IF(E31=$M$9,$M$7,IF(E31="",0,$M$15))),INDEX($M$16:$M$23,MATCH(E31,$L$16:$L$23,0))),IF(E31<$M$9,$M$14,IF(E31=$M$9,$M$7,IF(E31="",0,$M$15))))=0,"",IFERROR(IF(INDEX($M$16:$M$23,MATCH(E31,$L$16:$L$23,0))=0,IF(E31<$M$9,$M$14,IF(E31=$M$9,$M$7,IF(E31="",0,$M$15))),INDEX($M$16:$M$23,MATCH(E31,$L$16:$L$23,0))),IF(E31<$M$9,$M$14,IF(E31=$M$9,$M$7,IF(E31="",0,$M$15))))) -> 0.013541667 | G31: =IF(F31="","",IF(F31=0, 0, ROUNDDOWN(F31*$M$5,0.5))) -> 25729
D32: =IF(F32=$M$6,$L$6,IF(F32=$M$7,$L$7,"instalment")) -> instalment | E32: =IFERROR( IF( AND($M$9 >= E31, $M$9 <= EDATE(E31, $M$26), E31 <> $M$9), $M$9, IF( EDATE(E31, $M$26) <= EDATE($M$9, $M$13 * $M$26), EDATE(E31, $M$26), "" ) ), "") -> 47119 | F32: =IF(IFERROR(IF(INDEX($M$16:$M$23,MATCH(E32,$L$16:$L$23,0))=0,IF(E32<$M$9,$M$14,IF(E32=$M$9,$M$7,IF(E32="",0,$M$15))),INDEX($M$16:$M$23,MATCH(E32,$L$16:$L$23,0))),IF(E32<$M$9,$M$14,IF(E32=$M$9,$M$7,IF(E32="",0,$M$15))))=0,"",IFERROR(IF(INDEX($M$16:$M$23,MATCH(E32,$L$16:$L$23,0))=0,IF(E32<$M$9,$M$14,IF(E32=$M$9,$M$7,IF(E32="",0,$M$15))),INDEX($M$16:$M$23,MATCH(E32,$L$16:$L$23,0))),IF(E32<$M$9,$M$14,IF(E32=$M$9,$M$7,IF(E32="",0,$M$15))))) -> 0.013541667 | G32: =IF(F32="","",IF(F32=0, 0, ROUNDDOWN(F32*$M$5,0.5))) -> 25729
D33: =IF(F33=$M$6,$L$6,IF(F33=$M$7,$L$7,"instalment")) -> instalment | E33: =IFERROR( IF( AND($M$9 >= E32, $M$9 <= EDATE(E32, $M$26), E32 <> $M$9), $M$9, IF( EDATE(E32, $M$26) <= EDATE($M$9, $M$13 * $M$26), EDATE(E32, $M$26), "" ) ), "") -> 47150 | F33: =IF(IFERROR(IF(INDEX($M$16:$M$23,MATCH(E33,$L$16:$L$23,0))=0,IF(E33<$M$9,$M$14,IF(E33=$M$9,$M$7,IF(E33="",0,$M$15))),INDEX($M$16:$M$23,MATCH(E33,$L$16:$L$23,0))),IF(E33<$M$9,$M$14,IF(E33=$M$9,$M$7,IF(E33="",0,$M$15))))=0,"",IFERROR(IF(INDEX($M$16:$M$23,MATCH(E33,$L$16:$L$23,0))=0,IF(E33<$M$9,$M$14,IF(E33=$M$9,$M$7,IF(E33="",0,$M$15))),INDEX($M$16:$M$23,MATCH(E33,$L$16:$L$23,0))),IF(E33<$M$9,$M$14,IF(E33=$M$9,$M$7,IF(E33="",0,$M$15))))) -> 0.013541667 | G33: =IF(F33="","",IF(F33=0, 0, ROUNDDOWN(F33*$M$5,0.5))) -> 25729
D34: =IF(F34=$M$6,$L$6,IF(F34=$M$7,$L$7,"instalment")) -> instalment | E34: =IFERROR( IF( AND($M$9 >= E33, $M$9 <= EDATE(E33, $M$26), E33 <> $M$9), $M$9, IF( EDATE(E33, $M$26) <= EDATE($M$9, $M$13 * $M$26), EDATE(E33, $M$26), "" ) ), "") -> 47178 | F34: =IF(IFERROR(IF(INDEX($M$16:$M$23,MATCH(E34,$L$16:$L$23,0))=0,IF(E34<$M$9,$M$14,IF(E34=$M$9,$M$7,IF(E34="",0,$M$15))),INDEX($M$16:$M$23,MATCH(E34,$L$16:$L$23,0))),IF(E34<$M$9,$M$14,IF(E34=$M$9,$M$7,IF(E34="",0,$M$15))))=0,"",IFERROR(IF(INDEX($M$16:$M$23,MATCH(E34,$L$16:$L$23,0))=0,IF(E34<$M$9,$M$14,IF(E34=$M$9,$M$7,IF(E34="",0,$M$15))),INDEX($M$16:$M$23,MATCH(E34,$L$16:$L$23,0))),IF(E34<$M$9,$M$14,IF(E34=$M$9,$M$7,IF(E34="",0,$M$15))))) -> 0.013541667 | G34: =IF(F34="","",IF(F34=0, 0, ROUNDDOWN(F34*$M$5,0.5))) -> 25729
D35: =IF(F35=$M$6,$L$6,IF(F35=$M$7,$L$7,"instalment")) -> instalment | E35: =IFERROR( IF( AND($M$9 >= E34, $M$9 <= EDATE(E34, $M$26), E34 <> $M$9), $M$9, IF( EDATE(E34, $M$26) <= EDATE($M$9, $M$13 * $M$26), EDATE(E34, $M$26), "" ) ), "") -> 47209 | F35: =IF(IFERROR(IF(INDEX($M$16:$M$23,MATCH(E35,$L$16:$L$23,0))=0,IF(E35<$M$9,$M$14,IF(E35=$M$9,$M$7,IF(E35="",0,$M$15))),INDEX($M$16:$M$23,MATCH(E35,$L$16:$L$23,0))),IF(E35<$M$9,$M$14,IF(E35=$M$9,$M$7,IF(E35="",0,$M$15))))=0,"",IFERROR(IF(INDEX($M$16:$M$23,MATCH(E35,$L$16:$L$23,0))=0,IF(E35<$M$9,$M$14,IF(E35=$M$9,$M$7,IF(E35="",0,$M$15))),INDEX($M$16:$M$23,MATCH(E35,$L$16:$L$23,0))),IF(E35<$M$9,$M$14,IF(E35=$M$9,$M$7,IF(E35="",0,$M$15))))) -> 0.013541667 | G35: =IF(F35="","",IF(F35=0, 0, ROUNDDOWN(F35*$M$5,0.5))) -> 25729
D36: =IF(F36=$M$6,$L$6,IF(F36=$M$7,$L$7,"instalment")) -> instalment | E36: =IFERROR( IF( AND($M$9 >= E35, $M$9 <= EDATE(E35, $M$26), E35 <> $M$9), $M$9, IF( EDATE(E35, $M$26) <= EDATE($M$9, $M$13 * $M$26), EDATE(E35, $M$26), "" ) ), "") -> 47239 | F36: =IF(IFERROR(IF(INDEX($M$16:$M$23,MATCH(E36,$L$16:$L$23,0))=0,IF(E36<$M$9,$M$14,IF(E36=$M$9,$M$7,IF(E36="",0,$M$15))),INDEX($M$16:$M$23,MATCH(E36,$L$16:$L$23,0))),IF(E36<$M$9,$M$14,IF(E36=$M$9,$M$7,IF(E36="",0,$M$15))))=0,"",IFERROR(IF(INDEX($M$16:$M$23,MATCH(E36,$L$16:$L$23,0))=0,IF(E36<$M$9,$M$14,IF(E36=$M$9,$M$7,IF(E36="",0,$M$15))),INDEX($M$16:$M$23,MATCH(E36,$L$16:$L$23,0))),IF(E36<$M$9,$M$14,IF(E36=$M$9,$M$7,IF(E36="",0,$M$15))))) -> 0.013541667 | G36: =IF(F36="","",IF(F36=0, 0, ROUNDDOWN(F36*$M$5,0.5))) -> 25729
D37: =IF(F37=$M$6,$L$6,IF(F37=$M$7,$L$7,"instalment")) -> instalment | E37: =IFERROR( IF( AND($M$9 >= E36, $M$9 <= EDATE(E36, $M$26), E36 <> $M$9), $M$9, IF( EDATE(E36, $M$26) <= EDATE($M$9, $M$13 * $M$26), EDATE(E36, $M$26), "" ) ), "") -> 47270 | F37: =IF(IFERROR(IF(INDEX($M$16:$M$23,MATCH(E37,$L$16:$L$23,0))=0,IF(E37<$M$9,$M$14,IF(E37=$M$9,$M$7,IF(E37="",0,$M$15))),INDEX($M$16:$M$23,MATCH(E37,$L$16:$L$23,0))),IF(E37<$M$9,$M$14,IF(E37=$M$9,$M$7,IF(E37="",0,$M$15))))=0,"",IFERROR(IF(INDEX($M$16:$M$23,MATCH(E37,$L$16:$L$23,0))=0,IF(E37<$M$9,$M$14,IF(E37=$M$9,$M$7,IF(E37="",0,$M$15))),INDEX($M$16:$M$23,MATCH(E37,$L$16:$L$23,0))),IF(E37<$M$9,$M$14,IF(E37=$M$9,$M$7,IF(E37="",0,$M$15))))) -> 0.013541667 | G37: =IF(F37="","",IF(F37=0, 0, ROUNDDOWN(F37*$M$5,0.5))) -> 25729
D38: =IF(F38=$M$6,$L$6,IF(F38=$M$7,$L$7,"instalment")) -> instalment | E38: =IFERROR( IF( AND($M$9 >= E37, $M$9 <= EDATE(E37, $M$26), E37 <> $M$9), $M$9, IF( EDATE(E37, $M$26) <= EDATE($M$9, $M$13 * $M$26), EDATE(E37, $M$26), "" ) ), "") -> 47300 | F38: =IF(IFERROR(IF(INDEX($M$16:$M$23,MATCH(E38,$L$16:$L$23,0))=0,IF(E38<$M$9,$M$14,IF(E38=$M$9,$M$7,IF(E38="",0,$M$15))),INDEX($M$16:$M$23,MATCH(E38,$L$16:$L$23,0))),IF(E38<$M$9,$M$14,IF(E38=$M$9,$M$7,IF(E38="",0,$M$15))))=0,"",IFERROR(IF(INDEX($M$16:$M$23,MATCH(E38,$L$16:$L$23,0))=0,IF(E38<$M$9,$M$14,IF(E38=$M$9,$M$7,IF(E38="",0,$M$15))),INDEX($M$16:$M$23,MATCH(E38,$L$16:$L$23,0))),IF(E38<$M$9,$M$14,IF(E38=$M$9,$M$7,IF(E38="",0,$M$15))))) -> 0.013541667 | G38: =IF(F38="","",IF(F38=0, 0, ROUNDDOWN(F38*$M$5,0.5))) -> 25729
... D102: =IF(F102=$M$6,$L$6,IF(F102=$M$7,$L$7,"instalment")) -> instalment | E102: =IFERROR( IF( AND($M$9 >= E101, $M$9 <= EDATE(E101, $M$26), E101 <> $M$9), $M$9, IF( EDATE(E101, $M$26) <= EDATE($M$9, $M$13 * $M$26), EDATE(E101, $M$26), "" ) ), "") | F102: =IF(IFERROR(IF(INDEX($M$16:$M$23,MATCH(E102,$L$16:$L$23,0))=0,IF(E102<$M$9,$M$14,IF(E102=$M$9,$M$7,IF(E102="",0,$M$15))),INDEX($M$16:$M$23,MATCH(E102,$L$16:$L$23,0))),IF(E102<$M$9,$M$14,IF(E102=$M$9,$M$7,IF(E102="",0,$M$15))))=0,"",IFERROR(IF(INDEX($M$16:$M$23,MATCH(E102,$L$16:$L$23,0))=0,IF(E102<$M$9,$M$14,IF(E102=$M$9,$M$7,IF(E102="",0,$M$15))),INDEX($M$16:$M$23,MATCH(E102,$L$16:$L$23,0))),IF(E102<$M$9,$M$14,IF(E102=$M$9,$M$7,IF(E102="",0,$M$15))))) | G102: =IF(F102="","",IF(F102=0, 0, ROUNDDOWN(F102*$M$5,0.5)))

Sheet Payment Plan
B2: CHOOSE | C2: Semi Annual | E2: Price: | F2: 5000000
L5: INPUTS:
D6: =IF(F6=$M$6,$L$6,IF(F6=$M$7,$L$7,"instalment")) -> Down Payment | E6: 45962 | F6: =M6 -> 0.1 | G6: =J8 -> 500000 | I6: Total % | J6: =+SUM(F6:F102) -> 1 | L6: Down Payment | M6: 0.1
D7: =IF(F7=$M$6,$L$6,IF(F7=$M$7,$L$7,"instalment")) -> instalment | E7: =IFERROR( IF( AND($M$9 >= E6, $M$9 <= EDATE(E6, $M$22), E6 <> $M$9), $M$9, IF( EDATE(E6, $M$22) <= EDATE($M$9, $M$13 * $M$22), EDATE(E6, $M$22), "" ) ), "") -> 46143 | F7: =IF(IFERROR(IF(INDEX($M$16:$M$20,MATCH(E7,$L$16:$L$20,0))=0,IF(E7<$M$9,$M$14,IF(E7=$M$9,$M$7,IF(E7="",0,$M$15))),INDEX($M$16:$M$20,MATCH(E7,$L$16:$L$20,0))),IF(E7<$M$9,$M$14,IF(E7=$M$9,$M$7,IF(E7="",0,$M$15))))=0,"",IFERROR(IF(INDEX($M$16:$M$20,MATCH(E7,$L$16:$L$20,0))=0,IF(E7<$M$9,$M$14,IF(E7=$M$9,$M$7,IF(E7="",0,$M$15))),INDEX($M$16:$M$20,MATCH(E7,$L$16:$L$20,0))),IF(E7<$M$9,$M$14,IF(E7=$M$9,$M$7,IF(E7="",0,$M$15))))) -> 0.08 | G7: =+IFERROR(ROUNDUP(F7*$F$2,-0.5), "") -> 400000 | I7: QAR | J7: =+SUM(G7:G102) -> 4500000 | L7: Handover | M7: 0.15
D8: =IF(F8=$M$6,$L$6,IF(F8=$M$7,$L$7,"instalment")) -> instalment | E8: =IFERROR(IF(AND($M$9 >= E7, $M$9 <= EDATE(E7, $M$22), E7 <> $M$9), $M$9, IF( EDATE(E7, $M$22) <= EDATE($M$9, $M$13 * $M$22), EDATE(E7, $M$22), "" ) ), "") -> 46327 | F8: =IF(IFERROR(IF(INDEX($M$16:$M$20,MATCH(E8,$L$16:$L$20,0))=0,IF(E8<$M$9,$M$14,IF(E8=$M$9,$M$7,IF(E8="",0,$M$15))),INDEX($M$16:$M$20,MATCH(E8,$L$16:$L$20,0))),IF(E8<$M$9,$M$14,IF(E8=$M$9,$M$7,IF(E8="",0,$M$15))))=0,"",IFERROR(IF(INDEX($M$16:$M$20,MATCH(E8,$L$16:$L$20,0))=0,IF(E8<$M$9,$M$14,IF(E8=$M$9,$M$7,IF(E8="",0,$M$15))),INDEX($M$16:$M$20,MATCH(E8,$L$16:$L$20,0))),IF(E8<$M$9,$M$14,IF(E8=$M$9,$M$7,IF(E8="",0,$M$15))))) -> 0.08 | G8: =+IFERROR(ROUNDUP(F8*$F$2,-0.5), "") -> 400000 | I8: Diff. | J8: =F2-J7 -> 500000 | L8: Handover requirement | M8: 0.57
D9: =IF(F9=$M$6,$L$6,IF(F9=$M$7,$L$7,"instalment")) -> instalment | E9: =IFERROR( IF( AND($M$9 >= E8, $M$9 <= EDATE(E8, $M$22), E8 <> $M$9), $M$9, IF( EDATE(E8, $M$22) <= EDATE($M$9, $M$13 * $M$22), EDATE(E8, $M$22), "" ) ), "") -> 46508 | F9: =IF(IFERROR(IF(INDEX($M$16:$M$20,MATCH(E9,$L$16:$L$20,0))=0,IF(E9<$M$9,$M$14,IF(E9=$M$9,$M$7,IF(E9="",0,$M$15))),INDEX($M$16:$M$20,MATCH(E9,$L$16:$L$20,0))),IF(E9<$M$9,$M$14,IF(E9=$M$9,$M$7,IF(E9="",0,$M$15))))=0,"",IFERROR(IF(INDEX($M$16:$M$20,MATCH(E9,$L$16:$L$20,0))=0,IF(E9<$M$9,$M$14,IF(E9=$M$9,$M$7,IF(E9="",0,$M$15))),INDEX($M$16:$M$20,MATCH(E9,$L$16:$L$20,0))),IF(E9<$M$9,$M$14,IF(E9=$M$9,$M$7,IF(E9="",0,$M$15))))) -> 0.08 | G9: =+IFERROR(ROUNDUP(F9*$F$2,-0.5), "") -> 400000 | I9: Gross | J9: =SUM(J7:J8) -> 5000000 | L9: Handover date | M9: 46813
D10: =IF(F10=$M$6,$L$6,IF(F10=$M$7,$L$7,"instalment")) -> instalment | E10: =IFERROR( IF( AND($M$9 >= E9, $M$9 <= EDATE(E9, $M$22), E9 <> $M$9), $M$9, IF( EDATE(E9, $M$22) <= EDATE($M$9, $M$13 * $M$22), EDATE(E9, $M$22), "" ) ), "") -> 46692 | F10: =IF(IFERROR(IF(INDEX($M$16:$M$20,MATCH(E10,$L$16:$L$20,0))=0,IF(E10<$M$9,$M$14,IF(E10=$M$9,$M$7,IF(E10="",0,$M$15))),INDEX($M$16:$M$20,MATCH(E10,$L$16:$L$20,0))),IF(E10<$M$9,$M$14,IF(E10=$M$9,$M$7,IF(E10="",0,$M$15))))=0,"",IFERROR(IF(INDEX($M$16:$M$20,MATCH(E10,$L$16:$L$20,0))=0,IF(E10<$M$9,$M$14,IF(E10=$M$9,$M$7,IF(E10="",0,$M$15))),INDEX($M$16:$M$20,MATCH(E10,$L$16:$L$20,0))),IF(E10<$M$9,$M$14,IF(E10=$M$9,$M$7,IF(E10="",0,$M$15))))) -> 0.08 | G10: =+IFERROR(ROUNDUP(F10*$F$2,-0.5), "") -> 400000 | J10: =J8=G6 -> TRUE | L10: Days to handover | M10: =M9-E6 -> 851
D11: =IF(F11=$M$6,$L$6,IF(F11=$M$7,$L$7,"instalment")) -> Handover | E11: =IFERROR( IF( AND($M$9 >= E10, $M$9 <= EDATE(E10, $M$22), E10 <> $M$9), $M$9, IF( EDATE(E10, $M$22) <= EDATE($M$9, $M$13 * $M$22), EDATE(E10, $M$22), "" ) ), "") -> 46813 | F11: =IF(IFERROR(IF(INDEX($M$16:$M$20,MATCH(E11,$L$16:$L$20,0))=0,IF(E11<$M$9,$M$14,IF(E11=$M$9,$M$7,IF(E11="",0,$M$15))),INDEX($M$16:$M$20,MATCH(E11,$L$16:$L$20,0))),IF(E11<$M$9,$M$14,IF(E11=$M$9,$M$7,IF(E11="",0,$M$15))))=0,"",IFERROR(IF(INDEX($M$16:$M$20,MATCH(E11,$L$16:$L$20,0))=0,IF(E11<$M$9,$M$14,IF(E11=$M$9,$M$7,IF(E11="",0,$M$15))),INDEX($M$16:$M$20,MATCH(E11,$L$16:$L$20,0))),IF(E11<$M$9,$M$14,IF(E11=$M$9,$M$7,IF(E11="",0,$M$15))))) -> 0.15 | G11: =+IFERROR(ROUNDUP(F11*$F$2,-0.5), "") -> 750000 | L11: Pre-handover Periodicity | M11: =IF(M21="Monthly", ROUNDDOWN(M10/(30 * $M$22), 0)-1, ROUNDDOWN(M10/(30 * $M$22), 0)) -> 4
D12: =IF(F12=$M$6,$L$6,IF(F12=$M$7,$L$7,"instalment")) -> instalment | E12: =IFERROR( IF( AND($M$9 >= E11, $M$9 <= EDATE(E11, $M$22), E11 <> $M$9), $M$9, IF( EDATE(E11, $M$22) <= EDATE($M$9, $M$13 * $M$22), EDATE(E11, $M$22), "" ) ), "") -> 46997 | F12: =IF(IFERROR(IF(INDEX($M$16:$M$20,MATCH(E12,$L$16:$L$20,0))=0,IF(E12<$M$9,$M$14,IF(E12=$M$9,$M$7,IF(E12="",0,$M$15))),INDEX($M$16:$M$20,MATCH(E12,$L$16:$L$20,0))),IF(E12<$M$9,$M$14,IF(E12=$M$9,$M$7,IF(E12="",0,$M$15))))=0,"",IFERROR(IF(INDEX($M$16:$M$20,MATCH(E12,$L$16:$L$20,0))=0,IF(E12<$M$9,$M$14,IF(E12=$M$9,$M$7,IF(E12="",0,$M$15))),INDEX($M$16:$M$20,MATCH(E12,$L$16:$L$20,0))),IF(E12<$M$9,$M$14,IF(E12=$M$9,$M$7,IF(E12="",0,$M$15))))) -> 0.05375 | G12: =+IFERROR(ROUNDUP(F12*$F$2,-0.5), "") -> 268750 | L12: Post Handover Years | M12: 4
D13: =IF(F13=$M$6,$L$6,IF(F13=$M$7,$L$7,"instalment")) -> instalment | E13: =IFERROR( IF( AND($M$9 >= E12, $M$9 <= EDATE(E12, $M$22), E12 <> $M$9), $M$9, IF( EDATE(E12, $M$22) <= EDATE($M$9, $M$13 * $M$22), EDATE(E12, $M$22), "" ) ), "") -> 47178 | F13: =IF(IFERROR(IF(INDEX($M$16:$M$20,MATCH(E13,$L$16:$L$20,0))=0,IF(E13<$M$9,$M$14,IF(E13=$M$9,$M$7,IF(E13="",0,$M$15))),INDEX($M$16:$M$20,MATCH(E13,$L$16:$L$20,0))),IF(E13<$M$9,$M$14,IF(E13=$M$9,$M$7,IF(E13="",0,$M$15))))=0,"",IFERROR(IF(INDEX($M$16:$M$20,MATCH(E13,$L$16:$L$20,0))=0,IF(E13<$M$9,$M$14,IF(E13=$M$9,$M$7,IF(E13="",0,$M$15))),INDEX($M$16:$M$20,MATCH(E13,$L$16:$L$20,0))),IF(E13<$M$9,$M$14,IF(E13=$M$9,$M$7,IF(E13="",0,$M$15))))) -> 0.05375 | G13: =+IFERROR(ROUNDUP(F13*$F$2,-0.5), "") -> 268750 | L13: Post-Handover Periodicity | M13: =M12 * (12 / $M$22) -> 8
D14: =IF(F14=$M$6,$L$6,IF(F14=$M$7,$L$7,"instalment")) -> instalment | E14: =IFERROR( IF( AND($M$9 >= E13, $M$9 <= EDATE(E13, $M$22), E13 <> $M$9), $M$9, IF( EDATE(E13, $M$22) <= EDATE($M$9, $M$13 * $M$22), EDATE(E13, $M$22), "" ) ), "") -> 47362 | F14: =IF(IFERROR(IF(INDEX($M$16:$M$20,MATCH(E14,$L$16:$L$20,0))=0,IF(E14<$M$9,$M$14,IF(E14=$M$9,$M$7,IF(E14="",0,$M$15))),INDEX($M$16:$M$20,MATCH(E14,$L$16:$L$20,0))),IF(E14<$M$9,$M$14,IF(E14=$M$9,$M$7,IF(E14="",0,$M$15))))=0,"",IFERROR(IF(INDEX($M$16:$M$20,MATCH(E14,$L$16:$L$20,0))=0,IF(E14<$M$9,$M$14,IF(E14=$M$9,$M$7,IF(E14="",0,$M$15))),INDEX($M$16:$M$20,MATCH(E14,$L$16:$L$20,0))),IF(E14<$M$9,$M$14,IF(E14=$M$9,$M$7,IF(E14="",0,$M$15))))) -> 0.05375 | G14: =+IFERROR(ROUNDUP(F14*$F$2,-0.5), "") -> 268750 | L14: Pre-Handover pmt | M14: =(M8 - M7 - M6) / M11 -> 0.08
D15: =IF(F15=$M$6,$L$6,IF(F15=$M$7,$L$7,"instalment")) -> instalment | E15: =IFERROR( IF( AND($M$9 >= E14, $M$9 <= EDATE(E14, $M$22), E14 <> $M$9), $M$9, IF( EDATE(E14, $M$22) <= EDATE($M$9, $M$13 * $M$22), EDATE(E14, $M$22), "" ) ), "") -> 47543 | F15: =IF(IFERROR(IF(INDEX($M$16:$M$20,MATCH(E15,$L$16:$L$20,0))=0,IF(E15<$M$9,$M$14,IF(E15=$M$9,$M$7,IF(E15="",0,$M$15))),INDEX($M$16:$M$20,MATCH(E15,$L$16:$L$20,0))),IF(E15<$M$9,$M$14,IF(E15=$M$9,$M$7,IF(E15="",0,$M$15))))=0,"",IFERROR(IF(INDEX($M$16:$M$20,MATCH(E15,$L$16:$L$20,0))=0,IF(E15<$M$9,$M$14,IF(E15=$M$9,$M$7,IF(E15="",0,$M$15))),INDEX($M$16:$M$20,MATCH(E15,$L$16:$L$20,0))),IF(E15<$M$9,$M$14,IF(E15=$M$9,$M$7,IF(E15="",0,$M$15))))) -> 0.05375 | G15: =+IFERROR(ROUNDUP(F15*$F$2,-0.5), "") -> 268750 | L15: Post-Handover pmt | M15: =(1 - M8 - SUM(M16:M20)) / (M13 - COUNTIF(M16:M20, ">0")) -> 0.05375
D16: =IF(F16=$M$6,$L$6,IF(F16=$M$7,$L$7,"instalment")) -> instalment | E16: =IFERROR( IF( AND($M$9 >= E15, $M$9 <= EDATE(E15, $M$22), E15 <> $M$9), $M$9, IF( EDATE(E15, $M$22) <= EDATE($M$9, $M$13 * $M$22), EDATE(E15, $M$22), "" ) ), "") -> 47727 | F16: =IF(IFERROR(IF(INDEX($M$16:$M$20,MATCH(E16,$L$16:$L$20,0))=0,IF(E16<$M$9,$M$14,IF(E16=$M$9,$M$7,IF(E16="",0,$M$15))),INDEX($M$16:$M$20,MATCH(E16,$L$16:$L$20,0))),IF(E16<$M$9,$M$14,IF(E16=$M$9,$M$7,IF(E16="",0,$M$15))))=0,"",IFERROR(IF(INDEX($M$16:$M$20,MATCH(E16,$L$16:$L$20,0))=0,IF(E16<$M$9,$M$14,IF(E16=$M$9,$M$7,IF(E16="",0,$M$15))),INDEX($M$16:$M$20,MATCH(E16,$L$16:$L$20,0))),IF(E16<$M$9,$M$14,IF(E16=$M$9,$M$7,IF(E16="",0,$M$15))))) -> 0.05375 | G16: =+IFERROR(ROUNDUP(F16*$F$2,-0.5), "") -> 268750 | L16: 47757 | M16: 0
D17: =IF(F17=$M$6,$L$6,IF(F17=$M$7,$L$7,"instalment")) -> instalment | E17: =IFERROR( IF( AND($M$9 >= E16, $M$9 <= EDATE(E16, $M$22), E16 <> $M$9), $M$9, IF( EDATE(E16, $M$22) <= EDATE($M$9, $M$13 * $M$22), EDATE(E16, $M$22), "" ) ), "") -> 47908 | F17: =IF(IFERROR(IF(INDEX($M$16:$M$20,MATCH(E17,$L$16:$L$20,0))=0,IF(E17<$M$9,$M$14,IF(E17=$M$9,$M$7,IF(E17="",0,$M$15))),INDEX($M$16:$M$20,MATCH(E17,$L$16:$L$20,0))),IF(E17<$M$9,$M$14,IF(E17=$M$9,$M$7,IF(E17="",0,$M$15))))=0,"",IFERROR(IF(INDEX($M$16:$M$20,MATCH(E17,$L$16:$L$20,0))=0,IF(E17<$M$9,$M$14,IF(E17=$M$9,$M$7,IF(E17="",0,$M$15))),INDEX($M$16:$M$20,MATCH(E17,$L$16:$L$20,0))),IF(E17<$M$9,$M$14,IF(E17=$M$9,$M$7,IF(E17="",0,$M$15))))) -> 0.05375 | G17: =+IFERROR(ROUNDUP(F17*$F$2,-0.5), "") -> 268750 | L17: 47635 | M17: 0
D18: =IF(F18=$M$6,$L$6,IF(F18=$M$7,$L$7,"instalment")) -> instalment | E18: =IFERROR( IF( AND($M$9 >= E17, $M$9 <= EDATE(E17, $M$22), E17 <> $M$9), $M$9, IF( EDATE(E17, $M$22) <= EDATE($M$9, $M$13 * $M$22), EDATE(E17, $M$22), "" ) ), "") -> 48092 | F18: =IF(IFERROR(IF(INDEX($M$16:$M$20,MATCH(E18,$L$16:$L$20,0))=0,IF(E18<$M$9,$M$14,IF(E18=$M$9,$M$7,IF(E18="",0,$M$15))),INDEX($M$16:$M$20,MATCH(E18,$L$16:$L$20,0))),IF(E18<$M$9,$M$14,IF(E18=$M$9,$M$7,IF(E18="",0,$M$15))))=0,"",IFERROR(IF(INDEX($M$16:$M$20,MATCH(E18,$L$16:$L$20,0))=0,IF(E18<$M$9,$M$14,IF(E18=$M$9,$M$7,IF(E18="",0,$M$15))),INDEX($M$16:$M$20,MATCH(E18,$L$16:$L$20,0))),IF(E18<$M$9,$M$14,IF(E18=$M$9,$M$7,IF(E18="",0,$M$15))))) -> 0.05375 | G18: =+IFERROR(ROUNDUP(F18*$F$2,-0.5), "") -> 268750 | L18: 47818 | M18: 0
D19: =IF(F19=$M$6,$L$6,IF(F19=$M$7,$L$7,"instalment")) -> instalment | E19: =IFERROR( IF( AND($M$9 >= E18, $M$9 <= EDATE(E18, $M$22), E18 <> $M$9), $M$9, IF( EDATE(E18, $M$22) <= EDATE($M$9, $M$13 * $M$22), EDATE(E18, $M$22), "" ) ), "") -> 48274 | F19: =IF(IFERROR(IF(INDEX($M$16:$M$20,MATCH(E19,$L$16:$L$20,0))=0,IF(E19<$M$9,$M$14,IF(E19=$M$9,$M$7,IF(E19="",0,$M$15))),INDEX($M$16:$M$20,MATCH(E19,$L$16:$L$20,0))),IF(E19<$M$9,$M$14,IF(E19=$M$9,$M$7,IF(E19="",0,$M$15))))=0,"",IFERROR(IF(INDEX($M$16:$M$20,MATCH(E19,$L$16:$L$20,0))=0,IF(E19<$M$9,$M$14,IF(E19=$M$9,$M$7,IF(E19="",0,$M$15))),INDEX($M$16:$M$20,MATCH(E19,$L$16:$L$20,0))),IF(E19<$M$9,$M$14,IF(E19=$M$9,$M$7,IF(E19="",0,$M$15))))) -> 0.05375 | G19: =+IFERROR(ROUNDUP(F19*$F$2,-0.5), "") -> 268750 | L19: 48000 | M19: 0
D20: =IF(F20=$M$6,$L$6,IF(F20=$M$7,$L$7,"instalment")) -> instalment | E20: =IFERROR( IF( AND($M$9 >= E19, $M$9 <= EDATE(E19, $M$22), E19 <> $M$9), $M$9, IF( EDATE(E19, $M$22) <= EDATE($M$9, $M$13 * $M$22), EDATE(E19, $M$22), "" ) ), "") | F20: =IF(IFERROR(IF(INDEX($M$16:$M$20,MATCH(E20,$L$16:$L$20,0))=0,IF(E20<$M$9,$M$14,IF(E20=$M$9,$M$7,IF(E20="",0,$M$15))),INDEX($M$16:$M$20,MATCH(E20,$L$16:$L$20,0))),IF(E20<$M$9,$M$14,IF(E20=$M$9,$M$7,IF(E20="",0,$M$15))))=0,"",IFERROR(IF(INDEX($M$16:$M$20,MATCH(E20,$L$16:$L$20,0))=0,IF(E20<$M$9,$M$14,IF(E20=$M$9,$M$7,IF(E20="",0,$M$15))),INDEX($M$16:$M$20,MATCH(E20,$L$16:$L$20,0))),IF(E20<$M$9,$M$14,IF(E20=$M$9,$M$7,IF(E20="",0,$M$15))))) | G20: =+IFERROR(ROUNDUP(F20*$F$2,-0.5), "") | L20: 48183 | M20: 0
D21: =IF(F21=$M$6,$L$6,IF(F21=$M$7,$L$7,"instalment")) -> instalment | E21: =IFERROR( IF( AND($M$9 >= E20, $M$9 <= EDATE(E20, $M$22), E20 <> $M$9), $M$9, IF( EDATE(E20, $M$22) <= EDATE($M$9, $M$13 * $M$22), EDATE(E20, $M$22), "" ) ), "") | F21: =IF(IFERROR(IF(INDEX($M$16:$M$20,MATCH(E21,$L$16:$L$20,0))=0,IF(E21<$M$9,$M$14,IF(E21=$M$9,$M$7,IF(E21="",0,$M$15))),INDEX($M$16:$M$20,MATCH(E21,$L$16:$L$20,0))),IF(E21<$M$9,$M$14,IF(E21=$M$9,$M$7,IF(E21="",0,$M$15))))=0,"",IFERROR(IF(INDEX($M$16:$M$20,MATCH(E21,$L$16:$L$20,0))=0,IF(E21<$M$9,$M$14,IF(E21=$M$9,$M$7,IF(E21="",0,$M$15))),INDEX($M$16:$M$20,MATCH(E21,$L$16:$L$20,0))),IF(E21<$M$9,$M$14,IF(E21=$M$9,$M$7,IF(E21="",0,$M$15))))) | G21: =+IFERROR(ROUNDUP(F21*$F$2,-0.5), "") | L21: Frequency | M21: =C2 -> Semi Annual
D22: =IF(F22=$M$6,$L$6,IF(F22=$M$7,$L$7,"instalment")) -> instalment | E22: =IFERROR( IF( AND($M$9 >= E21, $M$9 <= EDATE(E21, $M$22), E21 <> $M$9), $M$9, IF( EDATE(E21, $M$22) <= EDATE($M$9, $M$13 * $M$22), EDATE(E21, $M$22), "" ) ), "") | F22: =IF(IFERROR(IF(INDEX($M$16:$M$20,MATCH(E22,$L$16:$L$20,0))=0,IF(E22<$M$9,$M$14,IF(E22=$M$9,$M$7,IF(E22="",0,$M$15))),INDEX($M$16:$M$20,MATCH(E22,$L$16:$L$20,0))),IF(E22<$M$9,$M$14,IF(E22=$M$9,$M$7,IF(E22="",0,$M$15))))=0,"",IFERROR(IF(INDEX($M$16:$M$20,MATCH(E22,$L$16:$L$20,0))=0,IF(E22<$M$9,$M$14,IF(E22=$M$9,$M$7,IF(E22="",0,$M$15))),INDEX($M$16:$M$20,MATCH(E22,$L$16:$L$20,0))),IF(E22<$M$9,$M$14,IF(E22=$M$9,$M$7,IF(E22="",0,$M$15))))) | G22: =+IFERROR(ROUNDUP(F22*$F$2,-0.5), "") | M22: =CHOOSE(MATCH(M21, {"Annual","Semi Annual","Quarterly","Monthly"}, 0), 12, 6, 3, 1) -> 6
D23: =IF(F23=$M$6,$L$6,IF(F23=$M$7,$L$7,"instalment")) -> instalment | E23: =IFERROR( IF( AND($M$9 >= E22, $M$9 <= EDATE(E22, $M$22), E22 <> $M$9), $M$9, IF( EDATE(E22, $M$22) <= EDATE($M$9, $M$13 * $M$22), EDATE(E22, $M$22), "" ) ), "") | F23: =IF(IFERROR(IF(INDEX($M$16:$M$20,MATCH(E23,$L$16:$L$20,0))=0,IF(E23<$M$9,$M$14,IF(E23=$M$9,$M$7,IF(E23="",0,$M$15))),INDEX($M$16:$M$20,MATCH(E23,$L$16:$L$20,0))),IF(E23<$M$9,$M$14,IF(E23=$M$9,$M$7,IF(E23="",0,$M$15))))=0,"",IFERROR(IF(INDEX($M$16:$M$20,MATCH(E23,$L$16:$L$20,0))=0,IF(E23<$M$9,$M$14,IF(E23=$M$9,$M$7,IF(E23="",0,$M$15))),INDEX($M$16:$M$20,MATCH(E23,$L$16:$L$20,0))),IF(E23<$M$9,$M$14,IF(E23=$M$9,$M$7,IF(E23="",0,$M$15))))) | G23: =+IFERROR(ROUNDUP(F23*$F$2,-0.5), "")
D24: =IF(F24=$M$6,$L$6,IF(F24=$M$7,$L$7,"instalment")) -> instalment | E24: =IFERROR( IF( AND($M$9 >= E23, $M$9 <= EDATE(E23, $M$22), E23 <> $M$9), $M$9, IF( EDATE(E23, $M$22) <= EDATE($M$9, $M$13 * $M$22), EDATE(E23, $M$22), "" ) ), "") | F24: =IF(IFERROR(IF(INDEX($M$16:$M$20,MATCH(E24,$L$16:$L$20,0))=0,IF(E24<$M$9,$M$14,IF(E24=$M$9,$M$7,IF(E24="",0,$M$15))),INDEX($M$16:$M$20,MATCH(E24,$L$16:$L$20,0))),IF(E24<$M$9,$M$14,IF(E24=$M$9,$M$7,IF(E24="",0,$M$15))))=0,"",IFERROR(IF(INDEX($M$16:$M$20,MATCH(E24,$L$16:$L$20,0))=0,IF(E24<$M$9,$M$14,IF(E24=$M$9,$M$7,IF(E24="",0,$M$15))),INDEX($M$16:$M$20,MATCH(E24,$L$16:$L$20,0))),IF(E24<$M$9,$M$14,IF(E24=$M$9,$M$7,IF(E24="",0,$M$15))))) | G24: =+IFERROR(ROUNDUP(F24*$F$2,-0.5), "")
D25: =IF(F25=$M$6,$L$6,IF(F25=$M$7,$L$7,"instalment")) -> instalment | E25: =IFERROR( IF( AND($M$9 >= E24, $M$9 <= EDATE(E24, $M$22), E24 <> $M$9), $M$9, IF( EDATE(E24, $M$22) <= EDATE($M$9, $M$13 * $M$22), EDATE(E24, $M$22), "" ) ), "") | F25: =IF(IFERROR(IF(INDEX($M$16:$M$20,MATCH(E25,$L$16:$L$20,0))=0,IF(E25<$M$9,$M$14,IF(E25=$M$9,$M$7,IF(E25="",0,$M$15))),INDEX($M$16:$M$20,MATCH(E25,$L$16:$L$20,0))),IF(E25<$M$9,$M$14,IF(E25=$M$9,$M$7,IF(E25="",0,$M$15))))=0,"",IFERROR(IF(INDEX($M$16:$M$20,MATCH(E25,$L$16:$L$20,0))=0,IF(E25<$M$9,$M$14,IF(E25=$M$9,$M$7,IF(E25="",0,$M$15))),INDEX($M$16:$M$20,MATCH(E25,$L$16:$L$20,0))),IF(E25<$M$9,$M$14,IF(E25=$M$9,$M$7,IF(E25="",0,$M$15))))) | G25: =+IFERROR(ROUNDUP(F25*$F$2,-0.5), "")
D26: =IF(F26=$M$6,$L$6,IF(F26=$M$7,$L$7,"instalment")) -> instalment | E26: =IFERROR( IF( AND($M$9 >= E25, $M$9 <= EDATE(E25, $M$22), E25 <> $M$9), $M$9, IF( EDATE(E25, $M$22) <= EDATE($M$9, $M$13 * $M$22), EDATE(E25, $M$22), "" ) ), "") | F26: =IF(IFERROR(IF(INDEX($M$16:$M$20,MATCH(E26,$L$16:$L$20,0))=0,IF(E26<$M$9,$M$14,IF(E26=$M$9,$M$7,IF(E26="",0,$M$15))),INDEX($M$16:$M$20,MATCH(E26,$L$16:$L$20,0))),IF(E26<$M$9,$M$14,IF(E26=$M$9,$M$7,IF(E26="",0,$M$15))))=0,"",IFERROR(IF(INDEX($M$16:$M$20,MATCH(E26,$L$16:$L$20,0))=0,IF(E26<$M$9,$M$14,IF(E26=$M$9,$M$7,IF(E26="",0,$M$15))),INDEX($M$16:$M$20,MATCH(E26,$L$16:$L$20,0))),IF(E26<$M$9,$M$14,IF(E26=$M$9,$M$7,IF(E26="",0,$M$15))))) | G26: =+IFERROR(ROUNDUP(F26*$F$2,-0.5), "")
D27: =IF(F27=$M$6,$L$6,IF(F27=$M$7,$L$7,"instalment")) -> instalment | E27: =IFERROR( IF( AND($M$9 >= E26, $M$9 <= EDATE(E26, $M$22), E26 <> $M$9), $M$9, IF( EDATE(E26, $M$22) <= EDATE($M$9, $M$13 * $M$22), EDATE(E26, $M$22), "" ) ), "") | F27: =IF(IFERROR(IF(INDEX($M$16:$M$20,MATCH(E27,$L$16:$L$20,0))=0,IF(E27<$M$9,$M$14,IF(E27=$M$9,$M$7,IF(E27="",0,$M$15))),INDEX($M$16:$M$20,MATCH(E27,$L$16:$L$20,0))),IF(E27<$M$9,$M$14,IF(E27=$M$9,$M$7,IF(E27="",0,$M$15))))=0,"",IFERROR(IF(INDEX($M$16:$M$20,MATCH(E27,$L$16:$L$20,0))=0,IF(E27<$M$9,$M$14,IF(E27=$M$9,$M$7,IF(E27="",0,$M$15))),INDEX($M$16:$M$20,MATCH(E27,$L$16:$L$20,0))),IF(E27<$M$9,$M$14,IF(E27=$M$9,$M$7,IF(E27="",0,$M$15))))) | G27: =+IFERROR(ROUNDUP(F27*$F$2,-0.5), "")
D28: =IF(F28=$M$6,$L$6,IF(F28=$M$7,$L$7,"instalment")) -> instalment | E28: =IFERROR( IF( AND($M$9 >= E27, $M$9 <= EDATE(E27, $M$22), E27 <> $M$9), $M$9, IF( EDATE(E27, $M$22) <= EDATE($M$9, $M$13 * $M$22), EDATE(E27, $M$22), "" ) ), "") | F28: =IF(IFERROR(IF(INDEX($M$16:$M$20,MATCH(E28,$L$16:$L$20,0))=0,IF(E28<$M$9,$M$14,IF(E28=$M$9,$M$7,IF(E28="",0,$M$15))),INDEX($M$16:$M$20,MATCH(E28,$L$16:$L$20,0))),IF(E28<$M$9,$M$14,IF(E28=$M$9,$M$7,IF(E28="",0,$M$15))))=0,"",IFERROR(IF(INDEX($M$16:$M$20,MATCH(E28,$L$16:$L$20,0))=0,IF(E28<$M$9,$M$14,IF(E28=$M$9,$M$7,IF(E28="",0,$M$15))),INDEX($M$16:$M$20,MATCH(E28,$L$16:$L$20,0))),IF(E28<$M$9,$M$14,IF(E28=$M$9,$M$7,IF(E28="",0,$M$15))))) | G28: =+IFERROR(ROUNDUP(F28*$F$2,-0.5), "")
D29: =IF(F29=$M$6,$L$6,IF(F29=$M$7,$L$7,"instalment")) -> instalment | E29: =IFERROR( IF( AND($M$9 >= E28, $M$9 <= EDATE(E28, $M$22), E28 <> $M$9), $M$9, IF( EDATE(E28, $M$22) <= EDATE($M$9, $M$13 * $M$22), EDATE(E28, $M$22), "" ) ), "") | F29: =IF(IFERROR(IF(INDEX($M$16:$M$20,MATCH(E29,$L$16:$L$20,0))=0,IF(E29<$M$9,$M$14,IF(E29=$M$9,$M$7,IF(E29="",0,$M$15))),INDEX($M$16:$M$20,MATCH(E29,$L$16:$L$20,0))),IF(E29<$M$9,$M$14,IF(E29=$M$9,$M$7,IF(E29="",0,$M$15))))=0,"",IFERROR(IF(INDEX($M$16:$M$20,MATCH(E29,$L$16:$L$20,0))=0,IF(E29<$M$9,$M$14,IF(E29=$M$9,$M$7,IF(E29="",0,$M$15))),INDEX($M$16:$M$20,MATCH(E29,$L$16:$L$20,0))),IF(E29<$M$9,$M$14,IF(E29=$M$9,$M$7,IF(E29="",0,$M$15))))) | G29: =+IFERROR(ROUNDUP(F29*$F$2,-0.5), "")
D30: =IF(F30=$M$6,$L$6,IF(F30=$M$7,$L$7,"instalment")) -> instalment | E30: =IFERROR( IF( AND($M$9 >= E29, $M$9 <= EDATE(E29, $M$22), E29 <> $M$9), $M$9, IF( EDATE(E29, $M$22) <= EDATE($M$9, $M$13 * $M$22), EDATE(E29, $M$22), "" ) ), "") | F30: =IF(IFERROR(IF(INDEX($M$16:$M$20,MATCH(E30,$L$16:$L$20,0))=0,IF(E30<$M$9,$M$14,IF(E30=$M$9,$M$7,IF(E30="",0,$M$15))),INDEX($M$16:$M$20,MATCH(E30,$L$16:$L$20,0))),IF(E30<$M$9,$M$14,IF(E30=$M$9,$M$7,IF(E30="",0,$M$15))))=0,"",IFERROR(IF(INDEX($M$16:$M$20,MATCH(E30,$L$16:$L$20,0))=0,IF(E30<$M$9,$M$14,IF(E30=$M$9,$M$7,IF(E30="",0,$M$15))),INDEX($M$16:$M$20,MATCH(E30,$L$16:$L$20,0))),IF(E30<$M$9,$M$14,IF(E30=$M$9,$M$7,IF(E30="",0,$M$15))))) | G30: =+IFERROR(ROUNDUP(F30*$F$2,-0.5), "")
D31: =IF(F31=$M$6,$L$6,IF(F31=$M$7,$L$7,"instalment")) -> instalment | E31: =IFERROR( IF( AND($M$9 >= E30, $M$9 <= EDATE(E30, $M$22), E30 <> $M$9), $M$9, IF( EDATE(E30, $M$22) <= EDATE($M$9, $M$13 * $M$22), EDATE(E30, $M$22), "" ) ), "") | F31: =IF(IFERROR(IF(INDEX($M$16:$M$20,MATCH(E31,$L$16:$L$20,0))=0,IF(E31<$M$9,$M$14,IF(E31=$M$9,$M$7,IF(E31="",0,$M$15))),INDEX($M$16:$M$20,MATCH(E31,$L$16:$L$20,0))),IF(E31<$M$9,$M$14,IF(E31=$M$9,$M$7,IF(E31="",0,$M$15))))=0,"",IFERROR(IF(INDEX($M$16:$M$20,MATCH(E31,$L$16:$L$20,0))=0,IF(E31<$M$9,$M$14,IF(E31=$M$9,$M$7,IF(E31="",0,$M$15))),INDEX($M$16:$M$20,MATCH(E31,$L$16:$L$20,0))),IF(E31<$M$9,$M$14,IF(E31=$M$9,$M$7,IF(E31="",0,$M$15))))) | G31: =+IFERROR(ROUNDUP(F31*$F$2,-0.5), "")
D32: =IF(F32=$M$6,$L$6,IF(F32=$M$7,$L$7,"instalment")) -> instalment | E32: =IFERROR( IF( AND($M$9 >= E31, $M$9 <= EDATE(E31, $M$22), E31 <> $M$9), $M$9, IF( EDATE(E31, $M$22) <= EDATE($M$9, $M$13 * $M$22), EDATE(E31, $M$22), "" ) ), "") | F32: =IF(IFERROR(IF(INDEX($M$16:$M$20,MATCH(E32,$L$16:$L$20,0))=0,IF(E32<$M$9,$M$14,IF(E32=$M$9,$M$7,IF(E32="",0,$M$15))),INDEX($M$16:$M$20,MATCH(E32,$L$16:$L$20,0))),IF(E32<$M$9,$M$14,IF(E32=$M$9,$M$7,IF(E32="",0,$M$15))))=0,"",IFERROR(IF(INDEX($M$16:$M$20,MATCH(E32,$L$16:$L$20,0))=0,IF(E32<$M$9,$M$14,IF(E32=$M$9,$M$7,IF(E32="",0,$M$15))),INDEX($M$16:$M$20,MATCH(E32,$L$16:$L$20,0))),IF(E32<$M$9,$M$14,IF(E32=$M$9,$M$7,IF(E32="",0,$M$15))))) | G32: =+IFERROR(ROUNDUP(F32*$F$2,-0.5), "")
D33: =IF(F33=$M$6,$L$6,IF(F33=$M$7,$L$7,"instalment")) -> instalment | E33: =IFERROR( IF( AND($M$9 >= E32, $M$9 <= EDATE(E32, $M$22), E32 <> $M$9), $M$9, IF( EDATE(E32, $M$22) <= EDATE($M$9, $M$13 * $M$22), EDATE(E32, $M$22), "" ) ), "") | F33: =IF(IFERROR(IF(INDEX($M$16:$M$20,MATCH(E33,$L$16:$L$20,0))=0,IF(E33<$M$9,$M$14,IF(E33=$M$9,$M$7,IF(E33="",0,$M$15))),INDEX($M$16:$M$20,MATCH(E33,$L$16:$L$20,0))),IF(E33<$M$9,$M$14,IF(E33=$M$9,$M$7,IF(E33="",0,$M$15))))=0,"",IFERROR(IF(INDEX($M$16:$M$20,MATCH(E33,$L$16:$L$20,0))=0,IF(E33<$M$9,$M$14,IF(E33=$M$9,$M$7,IF(E33="",0,$M$15))),INDEX($M$16:$M$20,MATCH(E33,$L$16:$L$20,0))),IF(E33<$M$9,$M$14,IF(E33=$M$9,$M$7,IF(E33="",0,$M$15))))) | G33: =+IFERROR(ROUNDUP(F33*$F$2,-0.5), "")
D34: =IF(F34=$M$6,$L$6,IF(F34=$M$7,$L$7,"instalment")) -> instalment | E34: =IFERROR( IF( AND($M$9 >= E33, $M$9 <= EDATE(E33, $M$22), E33 <> $M$9), $M$9, IF( EDATE(E33, $M$22) <= EDATE($M$9, $M$13 * $M$22), EDATE(E33, $M$22), "" ) ), "") | F34: =IF(IFERROR(IF(INDEX($M$16:$M$20,MATCH(E34,$L$16:$L$20,0))=0,IF(E34<$M$9,$M$14,IF(E34=$M$9,$M$7,IF(E34="",0,$M$15))),INDEX($M$16:$M$20,MATCH(E34,$L$16:$L$20,0))),IF(E34<$M$9,$M$14,IF(E34=$M$9,$M$7,IF(E34="",0,$M$15))))=0,"",IFERROR(IF(INDEX($M$16:$M$20,MATCH(E34,$L$16:$L$20,0))=0,IF(E34<$M$9,$M$14,IF(E34=$M$9,$M$7,IF(E34="",0,$M$15))),INDEX($M$16:$M$20,MATCH(E34,$L$16:$L$20,0))),IF(E34<$M$9,$M$14,IF(E34=$M$9,$M$7,IF(E34="",0,$M$15))))) | G34: =+IFERROR(ROUNDUP(F34*$F$2,-0.5), "")
... D102: =IF(F102=$M$6,$L$6,IF(F102=$M$7,$L$7,"instalment")) -> instalment | E102: =IFERROR( IF( AND($M$9 >= E101, $M$9 <= EDATE(E101, $M$22), E101 <> $M$9), $M$9, IF( EDATE(E101, $M$22) <= EDATE($M$9, $M$13 * $M$22), EDATE(E101, $M$22), "" ) ), "") | F102: =IF(IFERROR(IF(INDEX($M$16:$M$20,MATCH(E102,$L$16:$L$20,0))=0,IF(E102<$M$9,$M$14,IF(E102=$M$9,$M$7,IF(E102="",0,$M$15))),INDEX($M$16:$M$20,MATCH(E102,$L$16:$L$20,0))),IF(E102<$M$9,$M$14,IF(E102=$M$9,$M$7,IF(E102="",0,$M$15))))=0,"",IFERROR(IF(INDEX($M$16:$M$20,MATCH(E102,$L$16:$L$20,0))=0,IF(E102<$M$9,$M$14,IF(E102=$M$9,$M$7,IF(E102="",0,$M$15))),INDEX($M$16:$M$20,MATCH(E102,$L$16:$L$20,0))),IF(E102<$M$9,$M$14,IF(E102=$M$9,$M$7,IF(E102="",0,$M$15))))) | G102: =+IFERROR(ROUNDUP(F102*$F$2,-0.5), "")
